Log file created at: 2025/11/29 18:37:37
Running on machine: MSI
Running duration (h:mm:ss): 0:00:00
Log line format: [IWEF]yyyymmdd hh:mm:ss.uuuuuu threadid file:line] msg
I20251129 18:37:37.092137 29142 logger.hpp:55] Glog initialized. Log dir: ./logs
I20251129 18:37:37.092293 29142 main.cpp:90] [ReqID:-] Scheduler process starting...
I20251129 18:37:37.092300 29142 main.cpp:120] [ReqID:-] Initializing components...
I20251129 18:37:37.092304 29142 database_pool.h:28] Initializing DatabasePool with size: 20
I20251129 18:37:37.256410 29142 worker_manager.cpp:11] [ReqID:-] WorkerManager initialized. Timeout: 30s
I20251129 18:37:37.256450 29142 task_repository.cpp:19] [ReqID:-] TaskRepository initialized.
I20251129 18:37:37.257412 29142 scheduler_loop.cpp:19] [ReqID:-] SchedulerLoop initialized with dispatch thread pool size: 8
I20251129 18:37:37.257467 29142 scheduler_loop.cpp:20] [ReqID:-] SchedulerLoop initialized.
I20251129 18:37:37.257480 29142 scheduler_service_impl.cpp:28] [ReqID:-] SchedulerServiceImpl started.
I20251129 18:37:37.278659 29142 main.cpp:150] [ReqID:-] gRPC Server listening on 0.0.0.0:9090
I20251129 18:37:37.278695 29142 scheduler_loop.cpp:27] [ReqID:-] SchedulerLoop starting...
I20251129 18:37:37.278818 29142 main.cpp:159] [ReqID:-] Scheduler is running. Press Ctrl+C to stop.
I20251129 18:37:37.278842 29184 main.cpp:47] [ReqID:PATROL] PatrolLoop started.
W20251129 18:37:37.288810 29183 scheduler_loop.cpp:58] [ReqID:-] Pending tasks found (20) but no workers available!
W20251129 18:37:42.292276 29183 scheduler_loop.cpp:58] [ReqID:-] Pending tasks found (20) but no workers available!
W20251129 18:37:47.294888 29183 scheduler_loop.cpp:58] [ReqID:-] Pending tasks found (20) but no workers available!
W20251129 18:37:52.298734 29183 scheduler_loop.cpp:58] [ReqID:-] Pending tasks found (20) but no workers available!
W20251129 18:37:57.301433 29183 scheduler_loop.cpp:58] [ReqID:-] Pending tasks found (20) but no workers available!
W20251129 18:38:02.304265 29183 scheduler_loop.cpp:58] [ReqID:-] Pending tasks found (20) but no workers available!
I20251129 18:38:02.741560 29182 scheduler_service_impl.cpp:44] [ReqID:REG-worker-01] [Register] Worker registering from: 0.0.0.0:50051
I20251129 18:38:02.741606 29182 worker_manager.cpp:34] [ReqID:REG-worker-01] New Worker registered. ID: worker-01, Addr: 0.0.0.0:50051
I20251129 18:38:02.742839 29182 scheduler_service_impl.cpp:72] [Heartbeat] Sampled log from worker-01
I20251129 18:38:06.810442 29164 scheduler_loop.cpp:163] [ReqID:DISP-6e824220-fd27-481e-a15f-908787e74c1c] Successfully dispatched task 6e824220-fd27-481e-a15f-908787e74c1c to worker-01
I20251129 18:38:06.810988 29168 scheduler_loop.cpp:163] [ReqID:DISP-7cccc183-3c36-4a69-b816-46dfa830a909] Successfully dispatched task 7cccc183-3c36-4a69-b816-46dfa830a909 to worker-01
I20251129 18:38:06.811131 29163 scheduler_loop.cpp:163] [ReqID:DISP-3a0fd88e-9e4c-4d0e-9539-bc70c30bebe7] Successfully dispatched task 3a0fd88e-9e4c-4d0e-9539-bc70c30bebe7 to worker-01
I20251129 18:38:06.811141 29170 scheduler_loop.cpp:163] [ReqID:DISP-7bd5d622-de0e-4d49-bed0-f5f025177d73] Successfully dispatched task 7bd5d622-de0e-4d49-bed0-f5f025177d73 to worker-01
I20251129 18:38:06.811239 29165 scheduler_loop.cpp:163] [ReqID:DISP-b9f3f282-20db-48ac-a5b5-7521435d1e74] Successfully dispatched task b9f3f282-20db-48ac-a5b5-7521435d1e74 to worker-01
I20251129 18:38:06.811133 29167 scheduler_loop.cpp:163] [ReqID:DISP-e0d75346-6f8d-4b8b-9ccb-766bf054fb61] Successfully dispatched task e0d75346-6f8d-4b8b-9ccb-766bf054fb61 to worker-01
I20251129 18:38:06.811369 29169 scheduler_loop.cpp:163] [ReqID:DISP-a569287c-549a-4d69-9b2e-5f3e13c29d92] Successfully dispatched task a569287c-549a-4d69-9b2e-5f3e13c29d92 to worker-01
I20251129 18:38:06.811389 29166 scheduler_loop.cpp:163] [ReqID:DISP-d1663f17-7f14-4749-bf55-f039c252e62a] Successfully dispatched task d1663f17-7f14-4749-bf55-f039c252e62a to worker-01
I20251129 18:38:06.814950 29164 scheduler_loop.cpp:163] [ReqID:DISP-9a26c4f1-c6d5-44d1-9c3a-bae92fd936ec] Successfully dispatched task 9a26c4f1-c6d5-44d1-9c3a-bae92fd936ec to worker-01
I20251129 18:38:06.815867 29168 scheduler_loop.cpp:163] [ReqID:DISP-7a120d9a-097e-416f-9f4d-908e9a35c457] Successfully dispatched task 7a120d9a-097e-416f-9f4d-908e9a35c457 to worker-01
I20251129 18:38:06.814054 30496 scheduler_service_impl.cpp:106] [ReqID:UPD-3a0fd88e-9e4c-4d0e-9539-bc70c30bebe7] [UpdateTaskStatus] Task: 3a0fd88e-9e4c-4d0e-9539-bc70c30bebe7, State: SUCCESS
I20251129 18:38:06.814154 29182 scheduler_service_impl.cpp:106] [ReqID:UPD-7cccc183-3c36-4a69-b816-46dfa830a909] [UpdateTaskStatus] Task: 7cccc183-3c36-4a69-b816-46dfa830a909, State: SUCCESS
I20251129 18:38:06.814397 30562 scheduler_service_impl.cpp:106] [ReqID:UPD-e0d75346-6f8d-4b8b-9ccb-766bf054fb61] [UpdateTaskStatus] Task: e0d75346-6f8d-4b8b-9ccb-766bf054fb61, State: SUCCESS
I20251129 18:38:06.814249 30561 scheduler_service_impl.cpp:106] [ReqID:UPD-6e824220-fd27-481e-a15f-908787e74c1c] [UpdateTaskStatus] Task: 6e824220-fd27-481e-a15f-908787e74c1c, State: SUCCESS
I20251129 18:38:06.822882 29182 scheduler_service_impl.cpp:106] [ReqID:UPD-a569287c-549a-4d69-9b2e-5f3e13c29d92] [UpdateTaskStatus] Task: a569287c-549a-4d69-9b2e-5f3e13c29d92, State: SUCCESS
I20251129 18:38:06.823809 30561 scheduler_service_impl.cpp:106] [ReqID:UPD-7bd5d622-de0e-4d49-bed0-f5f025177d73] [UpdateTaskStatus] Task: 7bd5d622-de0e-4d49-bed0-f5f025177d73, State: SUCCESS
I20251129 18:38:06.824152 30563 scheduler_service_impl.cpp:106] [ReqID:UPD-b9f3f282-20db-48ac-a5b5-7521435d1e74] [UpdateTaskStatus] Task: b9f3f282-20db-48ac-a5b5-7521435d1e74, State: SUCCESS
I20251129 18:38:06.824265 30564 scheduler_service_impl.cpp:106] [ReqID:UPD-d1663f17-7f14-4749-bf55-f039c252e62a] [UpdateTaskStatus] Task: d1663f17-7f14-4749-bf55-f039c252e62a, State: SUCCESS
I20251129 18:38:06.828048 29182 scheduler_service_impl.cpp:106] [ReqID:UPD-9a26c4f1-c6d5-44d1-9c3a-bae92fd936ec] [UpdateTaskStatus] Task: 9a26c4f1-c6d5-44d1-9c3a-bae92fd936ec, State: SUCCESS
I20251129 18:38:06.828953 30564 scheduler_service_impl.cpp:106] [ReqID:UPD-7a120d9a-097e-416f-9f4d-908e9a35c457] [UpdateTaskStatus] Task: 7a120d9a-097e-416f-9f4d-908e9a35c457, State: SUCCESS
I20251129 18:38:07.306933 29170 scheduler_loop.cpp:163] [ReqID:DISP-6ddbc2cc-a1d9-440e-9278-f5881f032bfd] Successfully dispatched task 6ddbc2cc-a1d9-440e-9278-f5881f032bfd to worker-01
I20251129 18:38:07.307091 30563 scheduler_service_impl.cpp:106] [ReqID:UPD-6ddbc2cc-a1d9-440e-9278-f5881f032bfd] [UpdateTaskStatus] Task: 6ddbc2cc-a1d9-440e-9278-f5881f032bfd, State: SUCCESS
I20251129 18:38:07.321210 30563 scheduler_service_impl.cpp:106] [ReqID:UPD-49fd6755-ea52-484a-87ef-7869237a397b] [UpdateTaskStatus] Task: 49fd6755-ea52-484a-87ef-7869237a397b, State: SUCCESS
I20251129 18:38:07.321259 30565 scheduler_service_impl.cpp:106] [ReqID:UPD-1f72e94e-d0b3-4cd9-b139-3e12f3048ad2] [UpdateTaskStatus] Task: 1f72e94e-d0b3-4cd9-b139-3e12f3048ad2, State: SUCCESS
I20251129 18:38:07.321285 29167 scheduler_loop.cpp:163] [ReqID:DISP-1f72e94e-d0b3-4cd9-b139-3e12f3048ad2] Successfully dispatched task 1f72e94e-d0b3-4cd9-b139-3e12f3048ad2 to worker-01
I20251129 18:38:07.321591 29164 scheduler_loop.cpp:163] [ReqID:DISP-49fd6755-ea52-484a-87ef-7869237a397b] Successfully dispatched task 49fd6755-ea52-484a-87ef-7869237a397b to worker-01
I20251129 18:38:07.322422 29166 scheduler_loop.cpp:163] [ReqID:DISP-97dd9d37-ce5c-4322-b798-f53d833ccd96] Successfully dispatched task 97dd9d37-ce5c-4322-b798-f53d833ccd96 to worker-01
I20251129 18:38:07.322451 30582 scheduler_service_impl.cpp:106] [ReqID:UPD-97dd9d37-ce5c-4322-b798-f53d833ccd96] [UpdateTaskStatus] Task: 97dd9d37-ce5c-4322-b798-f53d833ccd96, State: SUCCESS
I20251129 18:38:07.322655 29169 scheduler_loop.cpp:163] [ReqID:DISP-c913dc2e-1d2a-49db-8942-770b4ce9fd97] Successfully dispatched task c913dc2e-1d2a-49db-8942-770b4ce9fd97 to worker-01
I20251129 18:38:07.323068 30583 scheduler_service_impl.cpp:106] [ReqID:UPD-44ec8bad-70e4-4316-a203-75f547b98e65] [UpdateTaskStatus] Task: 44ec8bad-70e4-4316-a203-75f547b98e65, State: SUCCESS
I20251129 18:38:07.323122 29163 scheduler_loop.cpp:163] [ReqID:DISP-ac6837b8-c73b-4270-8536-6cf807a9c2a4] Successfully dispatched task ac6837b8-c73b-4270-8536-6cf807a9c2a4 to worker-01
I20251129 18:38:07.323272 29168 scheduler_loop.cpp:163] [ReqID:DISP-44ec8bad-70e4-4316-a203-75f547b98e65] Successfully dispatched task 44ec8bad-70e4-4316-a203-75f547b98e65 to worker-01
I20251129 18:38:07.323354 29170 scheduler_loop.cpp:163] [ReqID:DISP-fecbd5c9-b2cd-41ae-b8b8-e8eb086a4f7c] Successfully dispatched task fecbd5c9-b2cd-41ae-b8b8-e8eb086a4f7c to worker-01
I20251129 18:38:07.324285 29165 scheduler_loop.cpp:163] [ReqID:DISP-2fee827f-4fe5-46c3-a232-789190c07551] Successfully dispatched task 2fee827f-4fe5-46c3-a232-789190c07551 to worker-01
I20251129 18:38:07.326997 29167 scheduler_loop.cpp:163] [ReqID:DISP-e0aa945e-24ad-4f69-8080-68dc22ed1238] Successfully dispatched task e0aa945e-24ad-4f69-8080-68dc22ed1238 to worker-01
I20251129 18:38:07.327463 30563 scheduler_service_impl.cpp:106] [ReqID:UPD-c913dc2e-1d2a-49db-8942-770b4ce9fd97] [UpdateTaskStatus] Task: c913dc2e-1d2a-49db-8942-770b4ce9fd97, State: SUCCESS
I20251129 18:38:07.327706 30584 scheduler_service_impl.cpp:106] [ReqID:UPD-ac6837b8-c73b-4270-8536-6cf807a9c2a4] [UpdateTaskStatus] Task: ac6837b8-c73b-4270-8536-6cf807a9c2a4, State: SUCCESS
I20251129 18:38:07.327908 30585 scheduler_service_impl.cpp:106] [ReqID:UPD-2fee827f-4fe5-46c3-a232-789190c07551] [UpdateTaskStatus] Task: 2fee827f-4fe5-46c3-a232-789190c07551, State: SUCCESS
I20251129 18:38:07.328083 30586 scheduler_service_impl.cpp:106] [ReqID:UPD-fecbd5c9-b2cd-41ae-b8b8-e8eb086a4f7c] [UpdateTaskStatus] Task: fecbd5c9-b2cd-41ae-b8b8-e8eb086a4f7c, State: SUCCESS
I20251129 18:38:07.331197 30584 scheduler_service_impl.cpp:106] [ReqID:UPD-e0aa945e-24ad-4f69-8080-68dc22ed1238] [UpdateTaskStatus] Task: e0aa945e-24ad-4f69-8080-68dc22ed1238, State: SUCCESS
I20251129 18:38:07.805915 29163 scheduler_loop.cpp:163] [ReqID:DISP-2027b474-7857-4781-a682-f4bd4eac3b0a] Successfully dispatched task 2027b474-7857-4781-a682-f4bd4eac3b0a to worker-01
I20251129 18:38:07.805981 30587 scheduler_service_impl.cpp:106] [ReqID:UPD-2027b474-7857-4781-a682-f4bd4eac3b0a] [UpdateTaskStatus] Task: 2027b474-7857-4781-a682-f4bd4eac3b0a, State: SUCCESS
I20251129 18:38:07.817050 29169 scheduler_loop.cpp:163] [ReqID:DISP-d68433f4-40fb-4249-84ad-6256b3481ee6] Successfully dispatched task d68433f4-40fb-4249-84ad-6256b3481ee6 to worker-01
I20251129 18:38:07.817104 29168 scheduler_loop.cpp:163] [ReqID:DISP-e9d00a22-90a8-4b7e-baaf-1f377cf1347a] Successfully dispatched task e9d00a22-90a8-4b7e-baaf-1f377cf1347a to worker-01
I20251129 18:38:07.817230 29166 scheduler_loop.cpp:163] [ReqID:DISP-383f003a-4ea6-4026-9759-2d493fdd8da9] Successfully dispatched task 383f003a-4ea6-4026-9759-2d493fdd8da9 to worker-01
I20251129 18:38:07.817445 30585 scheduler_service_impl.cpp:106] [ReqID:UPD-e9d00a22-90a8-4b7e-baaf-1f377cf1347a] [UpdateTaskStatus] Task: e9d00a22-90a8-4b7e-baaf-1f377cf1347a, State: SUCCESS
I20251129 18:38:07.817597 29165 scheduler_loop.cpp:163] [ReqID:DISP-46324b72-d82a-4203-9984-a7c27e327ff9] Successfully dispatched task 46324b72-d82a-4203-9984-a7c27e327ff9 to worker-01
I20251129 18:38:07.818053 29167 scheduler_loop.cpp:163] [ReqID:DISP-26cc3b0c-239a-46a3-bbb7-77f4e418b850] Successfully dispatched task 26cc3b0c-239a-46a3-bbb7-77f4e418b850 to worker-01
I20251129 18:38:07.817634 30587 scheduler_service_impl.cpp:106] [ReqID:UPD-383f003a-4ea6-4026-9759-2d493fdd8da9] [UpdateTaskStatus] Task: 383f003a-4ea6-4026-9759-2d493fdd8da9, State: SUCCESS
I20251129 18:38:07.817549 29164 scheduler_loop.cpp:163] [ReqID:DISP-7884f218-e879-40fe-9f05-e839bd540bf1] Successfully dispatched task 7884f218-e879-40fe-9f05-e839bd540bf1 to worker-01
I20251129 18:38:07.817584 29170 scheduler_loop.cpp:163] [ReqID:DISP-b6299032-6431-4dbb-b606-5658c7a9e2cc] Successfully dispatched task b6299032-6431-4dbb-b606-5658c7a9e2cc to worker-01
I20251129 18:38:07.817728 30593 scheduler_service_impl.cpp:106] [ReqID:UPD-7884f218-e879-40fe-9f05-e839bd540bf1] [UpdateTaskStatus] Task: 7884f218-e879-40fe-9f05-e839bd540bf1, State: SUCCESS
I20251129 18:38:07.818147 30594 scheduler_service_impl.cpp:106] [ReqID:UPD-d68433f4-40fb-4249-84ad-6256b3481ee6] [UpdateTaskStatus] Task: d68433f4-40fb-4249-84ad-6256b3481ee6, State: SUCCESS
I20251129 18:38:07.818806 29163 scheduler_loop.cpp:163] [ReqID:DISP-65d89ce1-251c-491d-b5b3-30480ea6f431] Successfully dispatched task 65d89ce1-251c-491d-b5b3-30480ea6f431 to worker-01
I20251129 18:38:07.821362 29168 scheduler_loop.cpp:163] [ReqID:DISP-673450c2-c83f-44a4-b3c3-980380ba3bfc] Successfully dispatched task 673450c2-c83f-44a4-b3c3-980380ba3bfc to worker-01
I20251129 18:38:07.821813 30585 scheduler_service_impl.cpp:106] [ReqID:UPD-b6299032-6431-4dbb-b606-5658c7a9e2cc] [UpdateTaskStatus] Task: b6299032-6431-4dbb-b606-5658c7a9e2cc, State: SUCCESS
I20251129 18:38:07.822059 30595 scheduler_service_impl.cpp:106] [ReqID:UPD-46324b72-d82a-4203-9984-a7c27e327ff9] [UpdateTaskStatus] Task: 46324b72-d82a-4203-9984-a7c27e327ff9, State: SUCCESS
I20251129 18:38:07.822118 30596 scheduler_service_impl.cpp:106] [ReqID:UPD-26cc3b0c-239a-46a3-bbb7-77f4e418b850] [UpdateTaskStatus] Task: 26cc3b0c-239a-46a3-bbb7-77f4e418b850, State: SUCCESS
I20251129 18:38:07.823711 30593 scheduler_service_impl.cpp:106] [ReqID:UPD-65d89ce1-251c-491d-b5b3-30480ea6f431] [UpdateTaskStatus] Task: 65d89ce1-251c-491d-b5b3-30480ea6f431, State: SUCCESS
I20251129 18:38:07.825434 30585 scheduler_service_impl.cpp:106] [ReqID:UPD-673450c2-c83f-44a4-b3c3-980380ba3bfc] [UpdateTaskStatus] Task: 673450c2-c83f-44a4-b3c3-980380ba3bfc, State: SUCCESS
I20251129 18:38:08.311465 29164 scheduler_loop.cpp:163] [ReqID:DISP-206b3368-7e11-46f9-b9e2-67b25919043f] Successfully dispatched task 206b3368-7e11-46f9-b9e2-67b25919043f to worker-01
I20251129 18:38:08.311468 30596 scheduler_service_impl.cpp:106] [ReqID:UPD-206b3368-7e11-46f9-b9e2-67b25919043f] [UpdateTaskStatus] Task: 206b3368-7e11-46f9-b9e2-67b25919043f, State: SUCCESS
I20251129 18:38:08.313092 29166 scheduler_loop.cpp:163] [ReqID:DISP-b7a0b4b3-e905-4d76-98ab-db07fd23df48] Successfully dispatched task b7a0b4b3-e905-4d76-98ab-db07fd23df48 to worker-01
I20251129 18:38:08.313139 30597 scheduler_service_impl.cpp:106] [ReqID:UPD-f474b5eb-f10b-4b46-b0bb-4cd6bb133bd7] [UpdateTaskStatus] Task: f474b5eb-f10b-4b46-b0bb-4cd6bb133bd7, State: SUCCESS
I20251129 18:38:08.313225 30607 scheduler_service_impl.cpp:106] [ReqID:UPD-3f8c574b-401a-4de7-9ab3-1cc166ed1a0c] [UpdateTaskStatus] Task: 3f8c574b-401a-4de7-9ab3-1cc166ed1a0c, State: SUCCESS
I20251129 18:38:08.313267 29163 scheduler_loop.cpp:163] [ReqID:DISP-f474b5eb-f10b-4b46-b0bb-4cd6bb133bd7] Successfully dispatched task f474b5eb-f10b-4b46-b0bb-4cd6bb133bd7 to worker-01
I20251129 18:38:08.313288 29170 scheduler_loop.cpp:163] [ReqID:DISP-3f8c574b-401a-4de7-9ab3-1cc166ed1a0c] Successfully dispatched task 3f8c574b-401a-4de7-9ab3-1cc166ed1a0c to worker-01
I20251129 18:38:08.313311 29168 scheduler_loop.cpp:163] [ReqID:DISP-33456f42-c980-488f-a6d0-57a419d1a4ee] Successfully dispatched task 33456f42-c980-488f-a6d0-57a419d1a4ee to worker-01
I20251129 18:38:08.313373 30608 scheduler_service_impl.cpp:106] [ReqID:UPD-33456f42-c980-488f-a6d0-57a419d1a4ee] [UpdateTaskStatus] Task: 33456f42-c980-488f-a6d0-57a419d1a4ee, State: SUCCESS
I20251129 18:38:08.313426 29165 scheduler_loop.cpp:163] [ReqID:DISP-73014dff-dbeb-4927-885e-215ed4cd4bd1] Successfully dispatched task 73014dff-dbeb-4927-885e-215ed4cd4bd1 to worker-01
I20251129 18:38:08.313441 29169 scheduler_loop.cpp:163] [ReqID:DISP-c6fd5657-8ad7-4555-af69-96e3540f19ca] Successfully dispatched task c6fd5657-8ad7-4555-af69-96e3540f19ca to worker-01
I20251129 18:38:08.313673 29167 scheduler_loop.cpp:163] [ReqID:DISP-d2b63f3b-b8c0-4c69-8b2e-9954104b4f0b] Successfully dispatched task d2b63f3b-b8c0-4c69-8b2e-9954104b4f0b to worker-01
I20251129 18:38:08.314987 29164 scheduler_loop.cpp:163] [ReqID:DISP-ee01cf1f-20d8-4500-9178-41f49efc858a] Successfully dispatched task ee01cf1f-20d8-4500-9178-41f49efc858a to worker-01
I20251129 18:38:08.315652 30596 scheduler_service_impl.cpp:106] [ReqID:UPD-b7a0b4b3-e905-4d76-98ab-db07fd23df48] [UpdateTaskStatus] Task: b7a0b4b3-e905-4d76-98ab-db07fd23df48, State: SUCCESS
I20251129 18:38:08.317077 30607 scheduler_service_impl.cpp:106] [ReqID:UPD-73014dff-dbeb-4927-885e-215ed4cd4bd1] [UpdateTaskStatus] Task: 73014dff-dbeb-4927-885e-215ed4cd4bd1, State: SUCCESS
I20251129 18:38:08.317123 30609 scheduler_service_impl.cpp:106] [ReqID:UPD-d2b63f3b-b8c0-4c69-8b2e-9954104b4f0b] [UpdateTaskStatus] Task: d2b63f3b-b8c0-4c69-8b2e-9954104b4f0b, State: SUCCESS
I20251129 18:38:08.317261 30610 scheduler_service_impl.cpp:106] [ReqID:UPD-c6fd5657-8ad7-4555-af69-96e3540f19ca] [UpdateTaskStatus] Task: c6fd5657-8ad7-4555-af69-96e3540f19ca, State: SUCCESS
I20251129 18:38:08.317162 29163 scheduler_loop.cpp:163] [ReqID:DISP-91425294-365c-44ff-babf-deadb21e78d3] Successfully dispatched task 91425294-365c-44ff-babf-deadb21e78d3 to worker-01
I20251129 18:38:08.319166 30596 scheduler_service_impl.cpp:106] [ReqID:UPD-ee01cf1f-20d8-4500-9178-41f49efc858a] [UpdateTaskStatus] Task: ee01cf1f-20d8-4500-9178-41f49efc858a, State: SUCCESS
I20251129 18:38:08.320508 30610 scheduler_service_impl.cpp:106] [ReqID:UPD-91425294-365c-44ff-babf-deadb21e78d3] [UpdateTaskStatus] Task: 91425294-365c-44ff-babf-deadb21e78d3, State: SUCCESS
I20251129 18:38:08.810438 29169 scheduler_loop.cpp:163] [ReqID:DISP-30548647-dd2e-4624-8d60-1ef140e1f362] Successfully dispatched task 30548647-dd2e-4624-8d60-1ef140e1f362 to worker-01
I20251129 18:38:08.810537 30611 scheduler_service_impl.cpp:106] [ReqID:UPD-30548647-dd2e-4624-8d60-1ef140e1f362] [UpdateTaskStatus] Task: 30548647-dd2e-4624-8d60-1ef140e1f362, State: SUCCESS
I20251129 18:38:08.811990 29163 scheduler_loop.cpp:163] [ReqID:DISP-0ecbbdbb-3ed1-4300-8c6e-401310b9f50e] Successfully dispatched task 0ecbbdbb-3ed1-4300-8c6e-401310b9f50e to worker-01
I20251129 18:38:08.811998 29165 scheduler_loop.cpp:163] [ReqID:DISP-b533c1a1-0f2d-424b-8d28-365cefb17a80] Successfully dispatched task b533c1a1-0f2d-424b-8d28-365cefb17a80 to worker-01
I20251129 18:38:08.812119 30607 scheduler_service_impl.cpp:106] [ReqID:UPD-9c5ceb8b-ca69-4583-bba0-d527676fdce6] [UpdateTaskStatus] Task: 9c5ceb8b-ca69-4583-bba0-d527676fdce6, State: SUCCESS
I20251129 18:38:08.812152 30622 scheduler_service_impl.cpp:106] [ReqID:UPD-0ecbbdbb-3ed1-4300-8c6e-401310b9f50e] [UpdateTaskStatus] Task: 0ecbbdbb-3ed1-4300-8c6e-401310b9f50e, State: SUCCESS
I20251129 18:38:08.812191 30623 scheduler_service_impl.cpp:106] [ReqID:UPD-b533c1a1-0f2d-424b-8d28-365cefb17a80] [UpdateTaskStatus] Task: b533c1a1-0f2d-424b-8d28-365cefb17a80, State: SUCCESS
I20251129 18:38:08.812462 29164 scheduler_loop.cpp:163] [ReqID:DISP-e100dc83-1f6e-4db9-b0e7-d96520df4794] Successfully dispatched task e100dc83-1f6e-4db9-b0e7-d96520df4794 to worker-01
I20251129 18:38:08.812460 29170 scheduler_loop.cpp:163] [ReqID:DISP-206011f4-289f-40db-a5b9-d33b6956a414] Successfully dispatched task 206011f4-289f-40db-a5b9-d33b6956a414 to worker-01
I20251129 18:38:08.812461 29168 scheduler_loop.cpp:163] [ReqID:DISP-9c5ceb8b-ca69-4583-bba0-d527676fdce6] Successfully dispatched task 9c5ceb8b-ca69-4583-bba0-d527676fdce6 to worker-01
I20251129 18:38:08.812474 29167 scheduler_loop.cpp:163] [ReqID:DISP-9a8f8dcf-f3b9-46be-9e75-7c51587b7ef8] Successfully dispatched task 9a8f8dcf-f3b9-46be-9e75-7c51587b7ef8 to worker-01
I20251129 18:38:08.812469 29166 scheduler_loop.cpp:163] [ReqID:DISP-f29bc6a1-14d0-46ed-b860-f071f7044e9e] Successfully dispatched task f29bc6a1-14d0-46ed-b860-f071f7044e9e to worker-01
I20251129 18:38:08.813800 29169 scheduler_loop.cpp:163] [ReqID:DISP-4a1efada-c007-41d7-8d90-d987b5312c6a] Successfully dispatched task 4a1efada-c007-41d7-8d90-d987b5312c6a to worker-01
I20251129 18:38:08.814776 30611 scheduler_service_impl.cpp:106] [ReqID:UPD-e100dc83-1f6e-4db9-b0e7-d96520df4794] [UpdateTaskStatus] Task: e100dc83-1f6e-4db9-b0e7-d96520df4794, State: SUCCESS
I20251129 18:38:08.815651 30607 scheduler_service_impl.cpp:106] [ReqID:UPD-206011f4-289f-40db-a5b9-d33b6956a414] [UpdateTaskStatus] Task: 206011f4-289f-40db-a5b9-d33b6956a414, State: SUCCESS
I20251129 18:38:08.815822 30624 scheduler_service_impl.cpp:106] [ReqID:UPD-f29bc6a1-14d0-46ed-b860-f071f7044e9e] [UpdateTaskStatus] Task: f29bc6a1-14d0-46ed-b860-f071f7044e9e, State: SUCCESS
I20251129 18:38:08.815891 29165 scheduler_loop.cpp:163] [ReqID:DISP-213d2913-5c75-4a30-8db2-2d078e657aa3] Successfully dispatched task 213d2913-5c75-4a30-8db2-2d078e657aa3 to worker-01
I20251129 18:38:08.816612 30622 scheduler_service_impl.cpp:106] [ReqID:UPD-9a8f8dcf-f3b9-46be-9e75-7c51587b7ef8] [UpdateTaskStatus] Task: 9a8f8dcf-f3b9-46be-9e75-7c51587b7ef8, State: SUCCESS
I20251129 18:38:08.818204 30611 scheduler_service_impl.cpp:106] [ReqID:UPD-4a1efada-c007-41d7-8d90-d987b5312c6a] [UpdateTaskStatus] Task: 4a1efada-c007-41d7-8d90-d987b5312c6a, State: SUCCESS
I20251129 18:38:08.819422 30607 scheduler_service_impl.cpp:106] [ReqID:UPD-213d2913-5c75-4a30-8db2-2d078e657aa3] [UpdateTaskStatus] Task: 213d2913-5c75-4a30-8db2-2d078e657aa3, State: SUCCESS
I20251129 18:38:09.312439 29168 scheduler_loop.cpp:163] [ReqID:DISP-72aef359-ce53-4276-9e7d-c9a07a0b80c3] Successfully dispatched task 72aef359-ce53-4276-9e7d-c9a07a0b80c3 to worker-01
I20251129 18:38:09.312531 29170 scheduler_loop.cpp:163] [ReqID:DISP-f18a0fc5-971e-4f24-9660-b76572ed78b6] Successfully dispatched task f18a0fc5-971e-4f24-9660-b76572ed78b6 to worker-01
I20251129 18:38:09.312610 30622 scheduler_service_impl.cpp:106] [ReqID:UPD-72aef359-ce53-4276-9e7d-c9a07a0b80c3] [UpdateTaskStatus] Task: 72aef359-ce53-4276-9e7d-c9a07a0b80c3, State: SUCCESS
I20251129 18:38:09.312672 30625 scheduler_service_impl.cpp:106] [ReqID:UPD-f18a0fc5-971e-4f24-9660-b76572ed78b6] [UpdateTaskStatus] Task: f18a0fc5-971e-4f24-9660-b76572ed78b6, State: SUCCESS
I20251129 18:38:09.313489 29167 scheduler_loop.cpp:163] [ReqID:DISP-220eb1ca-4e8d-48a0-895f-67e238a94578] Successfully dispatched task 220eb1ca-4e8d-48a0-895f-67e238a94578 to worker-01
I20251129 18:38:09.313553 29164 scheduler_loop.cpp:163] [ReqID:DISP-4237278e-92a7-45dd-b5ec-d7773d34e12c] Successfully dispatched task 4237278e-92a7-45dd-b5ec-d7773d34e12c to worker-01
I20251129 18:38:09.313654 30628 scheduler_service_impl.cpp:106] [ReqID:UPD-220eb1ca-4e8d-48a0-895f-67e238a94578] [UpdateTaskStatus] Task: 220eb1ca-4e8d-48a0-895f-67e238a94578, State: SUCCESS
I20251129 18:38:09.313939 30630 scheduler_service_impl.cpp:106] [ReqID:UPD-260f30e9-f141-4965-b719-3b81fe32a7d2] [UpdateTaskStatus] Task: 260f30e9-f141-4965-b719-3b81fe32a7d2, State: SUCCESS
I20251129 18:38:09.313949 29165 scheduler_loop.cpp:163] [ReqID:DISP-260f30e9-f141-4965-b719-3b81fe32a7d2] Successfully dispatched task 260f30e9-f141-4965-b719-3b81fe32a7d2 to worker-01
I20251129 18:38:09.314308 29166 scheduler_loop.cpp:163] [ReqID:DISP-9103994f-d9dc-4da0-97a2-4167f117f5a3] Successfully dispatched task 9103994f-d9dc-4da0-97a2-4167f117f5a3 to worker-01
I20251129 18:38:09.313973 29169 scheduler_loop.cpp:163] [ReqID:DISP-92135aad-4ece-4f90-a61c-f7cd3d17ff68] Successfully dispatched task 92135aad-4ece-4f90-a61c-f7cd3d17ff68 to worker-01
I20251129 18:38:09.314019 29163 scheduler_loop.cpp:163] [ReqID:DISP-53fddb1b-ebe3-428f-9235-5b9cf34ec524] Successfully dispatched task 53fddb1b-ebe3-428f-9235-5b9cf34ec524 to worker-01
I20251129 18:38:09.316965 29170 scheduler_loop.cpp:163] [ReqID:DISP-21bc6905-7eee-4854-96c1-19a541d590a8] Successfully dispatched task 21bc6905-7eee-4854-96c1-19a541d590a8 to worker-01
I20251129 18:38:09.317601 30630 scheduler_service_impl.cpp:106] [ReqID:UPD-4237278e-92a7-45dd-b5ec-d7773d34e12c] [UpdateTaskStatus] Task: 4237278e-92a7-45dd-b5ec-d7773d34e12c, State: SUCCESS
I20251129 18:38:09.317636 29168 scheduler_loop.cpp:163] [ReqID:DISP-ef15aa62-03c3-4974-837e-f5f1c279f562] Successfully dispatched task ef15aa62-03c3-4974-837e-f5f1c279f562 to worker-01
I20251129 18:38:09.317663 30631 scheduler_service_impl.cpp:106] [ReqID:UPD-92135aad-4ece-4f90-a61c-f7cd3d17ff68] [UpdateTaskStatus] Task: 92135aad-4ece-4f90-a61c-f7cd3d17ff68, State: SUCCESS
I20251129 18:38:09.317752 30632 scheduler_service_impl.cpp:106] [ReqID:UPD-53fddb1b-ebe3-428f-9235-5b9cf34ec524] [UpdateTaskStatus] Task: 53fddb1b-ebe3-428f-9235-5b9cf34ec524, State: SUCCESS
I20251129 18:38:09.318041 30633 scheduler_service_impl.cpp:106] [ReqID:UPD-9103994f-d9dc-4da0-97a2-4167f117f5a3] [UpdateTaskStatus] Task: 9103994f-d9dc-4da0-97a2-4167f117f5a3, State: SUCCESS
I20251129 18:38:09.320803 30630 scheduler_service_impl.cpp:106] [ReqID:UPD-21bc6905-7eee-4854-96c1-19a541d590a8] [UpdateTaskStatus] Task: 21bc6905-7eee-4854-96c1-19a541d590a8, State: SUCCESS
I20251129 18:38:09.321923 30632 scheduler_service_impl.cpp:106] [ReqID:UPD-ef15aa62-03c3-4974-837e-f5f1c279f562] [UpdateTaskStatus] Task: ef15aa62-03c3-4974-837e-f5f1c279f562, State: SUCCESS
I20251129 18:38:09.814021 29168 scheduler_loop.cpp:163] [ReqID:DISP-a50ac804-09b6-4dcc-9cc9-95367f4a33fc] Successfully dispatched task a50ac804-09b6-4dcc-9cc9-95367f4a33fc to worker-01
I20251129 18:38:09.814083 30634 scheduler_service_impl.cpp:106] [ReqID:UPD-a50ac804-09b6-4dcc-9cc9-95367f4a33fc] [UpdateTaskStatus] Task: a50ac804-09b6-4dcc-9cc9-95367f4a33fc, State: SUCCESS
I20251129 18:38:09.823364 29169 scheduler_loop.cpp:163] [ReqID:DISP-a76754c2-213e-4bc3-b579-4683dc3b4a01] Successfully dispatched task a76754c2-213e-4bc3-b579-4683dc3b4a01 to worker-01
I20251129 18:38:09.823487 29170 scheduler_loop.cpp:163] [ReqID:DISP-706eb97e-e73c-4ace-a3c3-7650c82965aa] Successfully dispatched task 706eb97e-e73c-4ace-a3c3-7650c82965aa to worker-01
I20251129 18:38:09.823659 30633 scheduler_service_impl.cpp:106] [ReqID:UPD-a76754c2-213e-4bc3-b579-4683dc3b4a01] [UpdateTaskStatus] Task: a76754c2-213e-4bc3-b579-4683dc3b4a01, State: SUCCESS
I20251129 18:38:09.823824 30634 scheduler_service_impl.cpp:106] [ReqID:UPD-706eb97e-e73c-4ace-a3c3-7650c82965aa] [UpdateTaskStatus] Task: 706eb97e-e73c-4ace-a3c3-7650c82965aa, State: SUCCESS
I20251129 18:38:09.823906 29164 scheduler_loop.cpp:163] [ReqID:DISP-9e715b31-19b0-4524-8167-c0775c210fb5] Successfully dispatched task 9e715b31-19b0-4524-8167-c0775c210fb5 to worker-01
I20251129 18:38:09.823962 29165 scheduler_loop.cpp:163] [ReqID:DISP-125284bb-9d88-4864-8aaa-0950481a2361] Successfully dispatched task 125284bb-9d88-4864-8aaa-0950481a2361 to worker-01
I20251129 18:38:09.823997 29166 scheduler_loop.cpp:163] [ReqID:DISP-7532cc87-f528-4e88-9556-dbb0469e6ae6] Successfully dispatched task 7532cc87-f528-4e88-9556-dbb0469e6ae6 to worker-01
I20251129 18:38:09.824049 30649 scheduler_service_impl.cpp:106] [ReqID:UPD-9e715b31-19b0-4524-8167-c0775c210fb5] [UpdateTaskStatus] Task: 9e715b31-19b0-4524-8167-c0775c210fb5, State: SUCCESS
I20251129 18:38:09.824196 30650 scheduler_service_impl.cpp:106] [ReqID:UPD-125284bb-9d88-4864-8aaa-0950481a2361] [UpdateTaskStatus] Task: 125284bb-9d88-4864-8aaa-0950481a2361, State: SUCCESS
I20251129 18:38:09.824103 29163 scheduler_loop.cpp:163] [ReqID:DISP-e653831b-5e24-4abb-9c3d-e1fab8363ace] Successfully dispatched task e653831b-5e24-4abb-9c3d-e1fab8363ace to worker-01
I20251129 18:38:09.824272 29167 scheduler_loop.cpp:163] [ReqID:DISP-8cfd68ea-7e88-41ab-991d-f0533c1568fb] Successfully dispatched task 8cfd68ea-7e88-41ab-991d-f0533c1568fb to worker-01
I20251129 18:38:09.824790 29168 scheduler_loop.cpp:163] [ReqID:DISP-786af7b3-ab88-4d4f-9664-71cfe93b42d8] Successfully dispatched task 786af7b3-ab88-4d4f-9664-71cfe93b42d8 to worker-01
I20251129 18:38:09.827246 29169 scheduler_loop.cpp:163] [ReqID:DISP-cae1f56b-8b03-4aec-b903-2d73df32e90c] Successfully dispatched task cae1f56b-8b03-4aec-b903-2d73df32e90c to worker-01
I20251129 18:38:09.828338 30649 scheduler_service_impl.cpp:106] [ReqID:UPD-7532cc87-f528-4e88-9556-dbb0469e6ae6] [UpdateTaskStatus] Task: 7532cc87-f528-4e88-9556-dbb0469e6ae6, State: SUCCESS
I20251129 18:38:09.828392 30651 scheduler_service_impl.cpp:106] [ReqID:UPD-8cfd68ea-7e88-41ab-991d-f0533c1568fb] [UpdateTaskStatus] Task: 8cfd68ea-7e88-41ab-991d-f0533c1568fb, State: SUCCESS
I20251129 18:38:09.828431 30652 scheduler_service_impl.cpp:106] [ReqID:UPD-786af7b3-ab88-4d4f-9664-71cfe93b42d8] [UpdateTaskStatus] Task: 786af7b3-ab88-4d4f-9664-71cfe93b42d8, State: SUCCESS
I20251129 18:38:09.828534 30653 scheduler_service_impl.cpp:106] [ReqID:UPD-e653831b-5e24-4abb-9c3d-e1fab8363ace] [UpdateTaskStatus] Task: e653831b-5e24-4abb-9c3d-e1fab8363ace, State: SUCCESS
I20251129 18:38:09.832077 30651 scheduler_service_impl.cpp:106] [ReqID:UPD-cae1f56b-8b03-4aec-b903-2d73df32e90c] [UpdateTaskStatus] Task: cae1f56b-8b03-4aec-b903-2d73df32e90c, State: SUCCESS
I20251129 18:38:10.319679 29165 scheduler_loop.cpp:163] [ReqID:DISP-549cd5b3-9a5c-4436-a9bd-a1a397ffaac4] Successfully dispatched task 549cd5b3-9a5c-4436-a9bd-a1a397ffaac4 to worker-01
I20251129 18:38:10.319702 30653 scheduler_service_impl.cpp:106] [ReqID:UPD-549cd5b3-9a5c-4436-a9bd-a1a397ffaac4] [UpdateTaskStatus] Task: 549cd5b3-9a5c-4436-a9bd-a1a397ffaac4, State: SUCCESS
I20251129 18:38:10.323750 29163 scheduler_loop.cpp:163] [ReqID:DISP-873d06f6-e7fa-494d-bc5b-2addf769b11f] Successfully dispatched task 873d06f6-e7fa-494d-bc5b-2addf769b11f to worker-01
I20251129 18:38:10.323992 29164 scheduler_loop.cpp:163] [ReqID:DISP-e60f0879-1730-4c74-b808-029c9adbc987] Successfully dispatched task e60f0879-1730-4c74-b808-029c9adbc987 to worker-01
I20251129 18:38:10.324074 29168 scheduler_loop.cpp:163] [ReqID:DISP-54cdcbe1-a3f1-430c-a84f-5f577d93bdbc] Successfully dispatched task 54cdcbe1-a3f1-430c-a84f-5f577d93bdbc to worker-01
I20251129 18:38:10.324083 30653 scheduler_service_impl.cpp:106] [ReqID:UPD-873d06f6-e7fa-494d-bc5b-2addf769b11f] [UpdateTaskStatus] Task: 873d06f6-e7fa-494d-bc5b-2addf769b11f, State: SUCCESS
I20251129 18:38:10.324384 29167 scheduler_loop.cpp:163] [ReqID:DISP-d0bf6bbc-2682-4bbf-9cda-307f70bd3e4b] Successfully dispatched task d0bf6bbc-2682-4bbf-9cda-307f70bd3e4b to worker-01
I20251129 18:38:10.325152 29169 scheduler_loop.cpp:163] [ReqID:DISP-b5abd3bd-6e84-4e78-b1f2-1fea08b424d1] Successfully dispatched task b5abd3bd-6e84-4e78-b1f2-1fea08b424d1 to worker-01
I20251129 18:38:10.325476 29166 scheduler_loop.cpp:163] [ReqID:DISP-f8055cad-c5a6-4156-a249-e5c27fc8e1fc] Successfully dispatched task f8055cad-c5a6-4156-a249-e5c27fc8e1fc to worker-01
I20251129 18:38:10.325538 29170 scheduler_loop.cpp:163] [ReqID:DISP-402d0d2f-04e8-45f1-baa4-ca0f9d80e1a9] Successfully dispatched task 402d0d2f-04e8-45f1-baa4-ca0f9d80e1a9 to worker-01
I20251129 18:38:10.325722 29165 scheduler_loop.cpp:163] [ReqID:DISP-94d9fa89-5063-4460-bc82-c277afacdb89] Successfully dispatched task 94d9fa89-5063-4460-bc82-c277afacdb89 to worker-01
I20251129 18:38:10.325875 30654 scheduler_service_impl.cpp:106] [ReqID:UPD-e60f0879-1730-4c74-b808-029c9adbc987] [UpdateTaskStatus] Task: e60f0879-1730-4c74-b808-029c9adbc987, State: SUCCESS
I20251129 18:38:10.325960 30661 scheduler_service_impl.cpp:106] [ReqID:UPD-54cdcbe1-a3f1-430c-a84f-5f577d93bdbc] [UpdateTaskStatus] Task: 54cdcbe1-a3f1-430c-a84f-5f577d93bdbc, State: SUCCESS
I20251129 18:38:10.325907 30660 scheduler_service_impl.cpp:106] [ReqID:UPD-d0bf6bbc-2682-4bbf-9cda-307f70bd3e4b] [UpdateTaskStatus] Task: d0bf6bbc-2682-4bbf-9cda-307f70bd3e4b, State: SUCCESS
I20251129 18:38:10.327641 29163 scheduler_loop.cpp:163] [ReqID:DISP-21c767b5-456b-4b58-9ccb-41e493d90534] Successfully dispatched task 21c767b5-456b-4b58-9ccb-41e493d90534 to worker-01
I20251129 18:38:10.328747 30653 scheduler_service_impl.cpp:106] [ReqID:UPD-94d9fa89-5063-4460-bc82-c277afacdb89] [UpdateTaskStatus] Task: 94d9fa89-5063-4460-bc82-c277afacdb89, State: SUCCESS
I20251129 18:38:10.330116 30661 scheduler_service_impl.cpp:106] [ReqID:UPD-b5abd3bd-6e84-4e78-b1f2-1fea08b424d1] [UpdateTaskStatus] Task: b5abd3bd-6e84-4e78-b1f2-1fea08b424d1, State: SUCCESS
I20251129 18:38:10.331575 30660 scheduler_service_impl.cpp:106] [ReqID:UPD-f8055cad-c5a6-4156-a249-e5c27fc8e1fc] [UpdateTaskStatus] Task: f8055cad-c5a6-4156-a249-e5c27fc8e1fc, State: SUCCESS
I20251129 18:38:10.331658 30662 scheduler_service_impl.cpp:106] [ReqID:UPD-402d0d2f-04e8-45f1-baa4-ca0f9d80e1a9] [UpdateTaskStatus] Task: 402d0d2f-04e8-45f1-baa4-ca0f9d80e1a9, State: SUCCESS
I20251129 18:38:10.333752 30653 scheduler_service_impl.cpp:106] [ReqID:UPD-21c767b5-456b-4b58-9ccb-41e493d90534] [UpdateTaskStatus] Task: 21c767b5-456b-4b58-9ccb-41e493d90534, State: SUCCESS
I20251129 18:38:10.819497 29165 scheduler_loop.cpp:163] [ReqID:DISP-651522f8-82df-4c9c-9a8a-007077f11a3a] Successfully dispatched task 651522f8-82df-4c9c-9a8a-007077f11a3a to worker-01
I20251129 18:38:10.819598 30661 scheduler_service_impl.cpp:106] [ReqID:UPD-651522f8-82df-4c9c-9a8a-007077f11a3a] [UpdateTaskStatus] Task: 651522f8-82df-4c9c-9a8a-007077f11a3a, State: SUCCESS
I20251129 18:38:10.828994 29163 scheduler_loop.cpp:163] [ReqID:DISP-62ca7a61-1745-4fd1-be86-20fe257ee64e] Successfully dispatched task 62ca7a61-1745-4fd1-be86-20fe257ee64e to worker-01
I20251129 18:38:10.829030 29170 scheduler_loop.cpp:163] [ReqID:DISP-680acbc1-7ec9-4f94-b2bb-e8e252173624] Successfully dispatched task 680acbc1-7ec9-4f94-b2bb-e8e252173624 to worker-01
I20251129 18:38:10.828994 29169 scheduler_loop.cpp:163] [ReqID:DISP-30ee96c1-0cf4-4141-9998-65d0fb03e466] Successfully dispatched task 30ee96c1-0cf4-4141-9998-65d0fb03e466 to worker-01
I20251129 18:38:10.829087 29168 scheduler_loop.cpp:163] [ReqID:DISP-b9f2c2a8-1205-4e52-88e7-02ce843a15fb] Successfully dispatched task b9f2c2a8-1205-4e52-88e7-02ce843a15fb to worker-01
I20251129 18:38:10.829138 30663 scheduler_service_impl.cpp:106] [ReqID:UPD-b9f2c2a8-1205-4e52-88e7-02ce843a15fb] [UpdateTaskStatus] Task: b9f2c2a8-1205-4e52-88e7-02ce843a15fb, State: SUCCESS
I20251129 18:38:10.829267 30661 scheduler_service_impl.cpp:106] [ReqID:UPD-30ee96c1-0cf4-4141-9998-65d0fb03e466] [UpdateTaskStatus] Task: 30ee96c1-0cf4-4141-9998-65d0fb03e466, State: SUCCESS
I20251129 18:38:10.829759 29167 scheduler_loop.cpp:163] [ReqID:DISP-495b0697-3eca-419a-8a5c-4b5b53acce6c] Successfully dispatched task 495b0697-3eca-419a-8a5c-4b5b53acce6c to worker-01
I20251129 18:38:10.829782 30681 scheduler_service_impl.cpp:106] [ReqID:UPD-62ca7a61-1745-4fd1-be86-20fe257ee64e] [UpdateTaskStatus] Task: 62ca7a61-1745-4fd1-be86-20fe257ee64e, State: SUCCESS
I20251129 18:38:10.829843 29166 scheduler_loop.cpp:163] [ReqID:DISP-146d8fd7-ab84-4a1d-a008-3ebc02a1ec73] Successfully dispatched task 146d8fd7-ab84-4a1d-a008-3ebc02a1ec73 to worker-01
I20251129 18:38:10.830004 30682 scheduler_service_impl.cpp:106] [ReqID:UPD-680acbc1-7ec9-4f94-b2bb-e8e252173624] [UpdateTaskStatus] Task: 680acbc1-7ec9-4f94-b2bb-e8e252173624, State: SUCCESS
I20251129 18:38:10.830052 29164 scheduler_loop.cpp:163] [ReqID:DISP-4983bd3d-775d-4461-a308-6da67bb33bef] Successfully dispatched task 4983bd3d-775d-4461-a308-6da67bb33bef to worker-01
I20251129 18:38:10.831223 29165 scheduler_loop.cpp:163] [ReqID:DISP-cac86033-b641-4a3e-8493-c6e314d02626] Successfully dispatched task cac86033-b641-4a3e-8493-c6e314d02626 to worker-01
I20251129 18:38:10.833302 29163 scheduler_loop.cpp:163] [ReqID:DISP-199090ee-27c4-4a4e-a8a8-dd90e4ca7b69] Successfully dispatched task 199090ee-27c4-4a4e-a8a8-dd90e4ca7b69 to worker-01
I20251129 18:38:10.834515 30682 scheduler_service_impl.cpp:106] [ReqID:UPD-495b0697-3eca-419a-8a5c-4b5b53acce6c] [UpdateTaskStatus] Task: 495b0697-3eca-419a-8a5c-4b5b53acce6c, State: SUCCESS
I20251129 18:38:10.834597 30683 scheduler_service_impl.cpp:106] [ReqID:UPD-146d8fd7-ab84-4a1d-a008-3ebc02a1ec73] [UpdateTaskStatus] Task: 146d8fd7-ab84-4a1d-a008-3ebc02a1ec73, State: SUCCESS
I20251129 18:38:10.834794 30684 scheduler_service_impl.cpp:106] [ReqID:UPD-4983bd3d-775d-4461-a308-6da67bb33bef] [UpdateTaskStatus] Task: 4983bd3d-775d-4461-a308-6da67bb33bef, State: SUCCESS
I20251129 18:38:10.834847 30685 scheduler_service_impl.cpp:106] [ReqID:UPD-cac86033-b641-4a3e-8493-c6e314d02626] [UpdateTaskStatus] Task: cac86033-b641-4a3e-8493-c6e314d02626, State: SUCCESS
I20251129 18:38:10.838220 30683 scheduler_service_impl.cpp:106] [ReqID:UPD-199090ee-27c4-4a4e-a8a8-dd90e4ca7b69] [UpdateTaskStatus] Task: 199090ee-27c4-4a4e-a8a8-dd90e4ca7b69, State: SUCCESS
I20251129 18:38:11.324728 29165 scheduler_loop.cpp:163] [ReqID:DISP-0e4f83d1-ad8a-4ce0-890b-b44469847d1c] Successfully dispatched task 0e4f83d1-ad8a-4ce0-890b-b44469847d1c to worker-01
I20251129 18:38:11.325083 30686 scheduler_service_impl.cpp:106] [ReqID:UPD-0e4f83d1-ad8a-4ce0-890b-b44469847d1c] [UpdateTaskStatus] Task: 0e4f83d1-ad8a-4ce0-890b-b44469847d1c, State: SUCCESS
I20251129 18:38:11.325779 30685 scheduler_service_impl.cpp:106] [ReqID:UPD-beb6d01d-ab55-48e7-8a53-7b5427bd99c6] [UpdateTaskStatus] Task: beb6d01d-ab55-48e7-8a53-7b5427bd99c6, State: SUCCESS
I20251129 18:38:11.326161 29170 scheduler_loop.cpp:163] [ReqID:DISP-9133f13b-7cfb-4d20-9282-3d0208c4c1d6] Successfully dispatched task 9133f13b-7cfb-4d20-9282-3d0208c4c1d6 to worker-01
I20251129 18:38:11.326192 29164 scheduler_loop.cpp:163] [ReqID:DISP-beb6d01d-ab55-48e7-8a53-7b5427bd99c6] Successfully dispatched task beb6d01d-ab55-48e7-8a53-7b5427bd99c6 to worker-01
I20251129 18:38:11.326200 29169 scheduler_loop.cpp:163] [ReqID:DISP-b332e79a-92ba-424d-b84c-93e8ff8e2814] Successfully dispatched task b332e79a-92ba-424d-b84c-93e8ff8e2814 to worker-01
I20251129 18:38:11.326330 30689 scheduler_service_impl.cpp:106] [ReqID:UPD-b332e79a-92ba-424d-b84c-93e8ff8e2814] [UpdateTaskStatus] Task: b332e79a-92ba-424d-b84c-93e8ff8e2814, State: SUCCESS
I20251129 18:38:11.326112 29167 scheduler_loop.cpp:163] [ReqID:DISP-23e041cd-0527-4721-b141-a42f64492125] Successfully dispatched task 23e041cd-0527-4721-b141-a42f64492125 to worker-01
I20251129 18:38:11.326512 30692 scheduler_service_impl.cpp:106] [ReqID:UPD-9133f13b-7cfb-4d20-9282-3d0208c4c1d6] [UpdateTaskStatus] Task: 9133f13b-7cfb-4d20-9282-3d0208c4c1d6, State: SUCCESS
I20251129 18:38:11.326481 29166 scheduler_loop.cpp:163] [ReqID:DISP-8a8bcff3-d7b8-45cb-b667-cb3a66ee82b5] Successfully dispatched task 8a8bcff3-d7b8-45cb-b667-cb3a66ee82b5 to worker-01
I20251129 18:38:11.326867 29168 scheduler_loop.cpp:163] [ReqID:DISP-c30064b4-95bf-400c-bb50-77a14159f806] Successfully dispatched task c30064b4-95bf-400c-bb50-77a14159f806 to worker-01
I20251129 18:38:11.327140 29163 scheduler_loop.cpp:163] [ReqID:DISP-87558f0a-04ac-435f-9b40-165d625bd7eb] Successfully dispatched task 87558f0a-04ac-435f-9b40-165d625bd7eb to worker-01
I20251129 18:38:11.338466 29165 scheduler_loop.cpp:163] [ReqID:DISP-c0773bba-1469-4858-90dc-166ab4f37629] Successfully dispatched task c0773bba-1469-4858-90dc-166ab4f37629 to worker-01
I20251129 18:38:11.339198 29170 scheduler_loop.cpp:163] [ReqID:DISP-c3e76ce4-d035-48aa-832f-a89af6e31db8] Successfully dispatched task c3e76ce4-d035-48aa-832f-a89af6e31db8 to worker-01
I20251129 18:38:11.339228 30692 scheduler_service_impl.cpp:106] [ReqID:UPD-c30064b4-95bf-400c-bb50-77a14159f806] [UpdateTaskStatus] Task: c30064b4-95bf-400c-bb50-77a14159f806, State: SUCCESS
I20251129 18:38:11.339629 30693 scheduler_service_impl.cpp:106] [ReqID:UPD-8a8bcff3-d7b8-45cb-b667-cb3a66ee82b5] [UpdateTaskStatus] Task: 8a8bcff3-d7b8-45cb-b667-cb3a66ee82b5, State: SUCCESS
I20251129 18:38:11.339685 30694 scheduler_service_impl.cpp:106] [ReqID:UPD-23e041cd-0527-4721-b141-a42f64492125] [UpdateTaskStatus] Task: 23e041cd-0527-4721-b141-a42f64492125, State: SUCCESS
I20251129 18:38:11.339773 30695 scheduler_service_impl.cpp:106] [ReqID:UPD-87558f0a-04ac-435f-9b40-165d625bd7eb] [UpdateTaskStatus] Task: 87558f0a-04ac-435f-9b40-165d625bd7eb, State: SUCCESS
I20251129 18:38:11.350209 30692 scheduler_service_impl.cpp:106] [ReqID:UPD-c0773bba-1469-4858-90dc-166ab4f37629] [UpdateTaskStatus] Task: c0773bba-1469-4858-90dc-166ab4f37629, State: SUCCESS
I20251129 18:38:11.350610 30694 scheduler_service_impl.cpp:106] [ReqID:UPD-c3e76ce4-d035-48aa-832f-a89af6e31db8] [UpdateTaskStatus] Task: c3e76ce4-d035-48aa-832f-a89af6e31db8, State: SUCCESS
I20251129 18:38:11.838388 29167 scheduler_loop.cpp:163] [ReqID:DISP-f593b6e3-e8a2-44db-bf5a-6717458a285c] Successfully dispatched task f593b6e3-e8a2-44db-bf5a-6717458a285c to worker-01
I20251129 18:38:11.838990 30692 scheduler_service_impl.cpp:106] [ReqID:UPD-f593b6e3-e8a2-44db-bf5a-6717458a285c] [UpdateTaskStatus] Task: f593b6e3-e8a2-44db-bf5a-6717458a285c, State: SUCCESS
I20251129 18:38:11.839077 30696 scheduler_service_impl.cpp:106] [ReqID:UPD-f5f82d09-95d8-4955-b02a-e70a43623ae5] [UpdateTaskStatus] Task: f5f82d09-95d8-4955-b02a-e70a43623ae5, State: SUCCESS
I20251129 18:38:11.839469 29163 scheduler_loop.cpp:163] [ReqID:DISP-9d8e9da5-883d-4608-86d5-9dbb4e93875c] Successfully dispatched task 9d8e9da5-883d-4608-86d5-9dbb4e93875c to worker-01
I20251129 18:38:11.839664 30702 scheduler_service_impl.cpp:106] [ReqID:UPD-2ddb0592-dc61-491e-b232-46d50c2ebfa9] [UpdateTaskStatus] Task: 2ddb0592-dc61-491e-b232-46d50c2ebfa9, State: SUCCESS
I20251129 18:38:11.839749 29170 scheduler_loop.cpp:163] [ReqID:DISP-1434dd24-fd7d-4095-9443-003541cbe4b3] Successfully dispatched task 1434dd24-fd7d-4095-9443-003541cbe4b3 to worker-01
I20251129 18:38:11.839766 30703 scheduler_service_impl.cpp:106] [ReqID:UPD-9d8e9da5-883d-4608-86d5-9dbb4e93875c] [UpdateTaskStatus] Task: 9d8e9da5-883d-4608-86d5-9dbb4e93875c, State: SUCCESS
I20251129 18:38:11.840251 29169 scheduler_loop.cpp:163] [ReqID:DISP-f5f82d09-95d8-4955-b02a-e70a43623ae5] Successfully dispatched task f5f82d09-95d8-4955-b02a-e70a43623ae5 to worker-01
I20251129 18:38:11.840282 29166 scheduler_loop.cpp:163] [ReqID:DISP-2ddb0592-dc61-491e-b232-46d50c2ebfa9] Successfully dispatched task 2ddb0592-dc61-491e-b232-46d50c2ebfa9 to worker-01
I20251129 18:38:11.840672 29164 scheduler_loop.cpp:163] [ReqID:DISP-f8aa6369-b54f-416e-abc7-ee2983385748] Successfully dispatched task f8aa6369-b54f-416e-abc7-ee2983385748 to worker-01
I20251129 18:38:11.840680 29168 scheduler_loop.cpp:163] [ReqID:DISP-0c7899d3-5388-4121-90e9-70ce4f1b7f8b] Successfully dispatched task 0c7899d3-5388-4121-90e9-70ce4f1b7f8b to worker-01
I20251129 18:38:11.840726 29165 scheduler_loop.cpp:163] [ReqID:DISP-6146e74c-e639-4645-80f4-bfcf433c74c3] Successfully dispatched task 6146e74c-e639-4645-80f4-bfcf433c74c3 to worker-01
I20251129 18:38:11.842589 29167 scheduler_loop.cpp:163] [ReqID:DISP-2808c710-8918-4972-86cb-64379c643161] Successfully dispatched task 2808c710-8918-4972-86cb-64379c643161 to worker-01
I20251129 18:38:11.843628 30696 scheduler_service_impl.cpp:106] [ReqID:UPD-f8aa6369-b54f-416e-abc7-ee2983385748] [UpdateTaskStatus] Task: f8aa6369-b54f-416e-abc7-ee2983385748, State: SUCCESS
I20251129 18:38:11.843875 30704 scheduler_service_impl.cpp:106] [ReqID:UPD-1434dd24-fd7d-4095-9443-003541cbe4b3] [UpdateTaskStatus] Task: 1434dd24-fd7d-4095-9443-003541cbe4b3, State: SUCCESS
I20251129 18:38:11.843995 30705 scheduler_service_impl.cpp:106] [ReqID:UPD-6146e74c-e639-4645-80f4-bfcf433c74c3] [UpdateTaskStatus] Task: 6146e74c-e639-4645-80f4-bfcf433c74c3, State: SUCCESS
I20251129 18:38:11.844010 29163 scheduler_loop.cpp:163] [ReqID:DISP-12be3a4d-3e1c-41c5-b107-2e9f8f175ee8] Successfully dispatched task 12be3a4d-3e1c-41c5-b107-2e9f8f175ee8 to worker-01
I20251129 18:38:11.844043 30706 scheduler_service_impl.cpp:106] [ReqID:UPD-0c7899d3-5388-4121-90e9-70ce4f1b7f8b] [UpdateTaskStatus] Task: 0c7899d3-5388-4121-90e9-70ce4f1b7f8b, State: SUCCESS
I20251129 18:38:11.847079 30696 scheduler_service_impl.cpp:106] [ReqID:UPD-2808c710-8918-4972-86cb-64379c643161] [UpdateTaskStatus] Task: 2808c710-8918-4972-86cb-64379c643161, State: SUCCESS
I20251129 18:38:11.847853 30704 scheduler_service_impl.cpp:106] [ReqID:UPD-12be3a4d-3e1c-41c5-b107-2e9f8f175ee8] [UpdateTaskStatus] Task: 12be3a4d-3e1c-41c5-b107-2e9f8f175ee8, State: SUCCESS
I20251129 18:38:12.327379 29163 scheduler_loop.cpp:163] [ReqID:DISP-e9ab1338-692d-44e6-8e10-7ab325c65d5e] Successfully dispatched task e9ab1338-692d-44e6-8e10-7ab325c65d5e to worker-01
I20251129 18:38:12.327468 30696 scheduler_service_impl.cpp:106] [ReqID:UPD-e9ab1338-692d-44e6-8e10-7ab325c65d5e] [UpdateTaskStatus] Task: e9ab1338-692d-44e6-8e10-7ab325c65d5e, State: SUCCESS
I20251129 18:38:12.345031 29169 scheduler_loop.cpp:163] [ReqID:DISP-d880fa71-4e8b-41ff-97be-f37dfd300b03] Successfully dispatched task d880fa71-4e8b-41ff-97be-f37dfd300b03 to worker-01
I20251129 18:38:12.345158 29170 scheduler_loop.cpp:163] [ReqID:DISP-ba353cd7-cdf5-45a7-9ec8-93def0a4d07d] Successfully dispatched task ba353cd7-cdf5-45a7-9ec8-93def0a4d07d to worker-01
I20251129 18:38:12.345340 29165 scheduler_loop.cpp:163] [ReqID:DISP-dc2126aa-af3d-431f-9101-3b4554ceb74c] Successfully dispatched task dc2126aa-af3d-431f-9101-3b4554ceb74c to worker-01
I20251129 18:38:12.345752 29166 scheduler_loop.cpp:163] [ReqID:DISP-c80f51a9-818f-4825-9695-17c78889567d] Successfully dispatched task c80f51a9-818f-4825-9695-17c78889567d to worker-01
I20251129 18:38:12.345358 30707 scheduler_service_impl.cpp:106] [ReqID:UPD-d880fa71-4e8b-41ff-97be-f37dfd300b03] [UpdateTaskStatus] Task: d880fa71-4e8b-41ff-97be-f37dfd300b03, State: SUCCESS
I20251129 18:38:12.345813 29167 scheduler_loop.cpp:163] [ReqID:DISP-f8735dfd-6d56-4f23-9ef0-57abaadb6605] Successfully dispatched task f8735dfd-6d56-4f23-9ef0-57abaadb6605 to worker-01
I20251129 18:38:12.345422 30696 scheduler_service_impl.cpp:106] [ReqID:UPD-dc2126aa-af3d-431f-9101-3b4554ceb74c] [UpdateTaskStatus] Task: dc2126aa-af3d-431f-9101-3b4554ceb74c, State: SUCCESS
I20251129 18:38:12.345467 30722 scheduler_service_impl.cpp:106] [ReqID:UPD-ba353cd7-cdf5-45a7-9ec8-93def0a4d07d] [UpdateTaskStatus] Task: ba353cd7-cdf5-45a7-9ec8-93def0a4d07d, State: SUCCESS
I20251129 18:38:12.345533 29164 scheduler_loop.cpp:163] [ReqID:DISP-64adcf8d-077a-4afd-b081-ac7f3a285e1a] Successfully dispatched task 64adcf8d-077a-4afd-b081-ac7f3a285e1a to worker-01
I20251129 18:38:12.345650 30723 scheduler_service_impl.cpp:106] [ReqID:UPD-64adcf8d-077a-4afd-b081-ac7f3a285e1a] [UpdateTaskStatus] Task: 64adcf8d-077a-4afd-b081-ac7f3a285e1a, State: SUCCESS
I20251129 18:38:12.345726 29168 scheduler_loop.cpp:163] [ReqID:DISP-557e7e31-3b02-46e7-b67b-cee7f26255b6] Successfully dispatched task 557e7e31-3b02-46e7-b67b-cee7f26255b6 to worker-01
I20251129 18:38:12.347257 29163 scheduler_loop.cpp:163] [ReqID:DISP-a6010ba8-462d-48ca-8688-5f818bae6605] Successfully dispatched task a6010ba8-462d-48ca-8688-5f818bae6605 to worker-01
I20251129 18:38:12.349591 29169 scheduler_loop.cpp:163] [ReqID:DISP-62631ac9-cd52-4349-a9fa-bb1928d32814] Successfully dispatched task 62631ac9-cd52-4349-a9fa-bb1928d32814 to worker-01
I20251129 18:38:12.350216 30723 scheduler_service_impl.cpp:106] [ReqID:UPD-557e7e31-3b02-46e7-b67b-cee7f26255b6] [UpdateTaskStatus] Task: 557e7e31-3b02-46e7-b67b-cee7f26255b6, State: SUCCESS
I20251129 18:38:12.350538 30724 scheduler_service_impl.cpp:106] [ReqID:UPD-c80f51a9-818f-4825-9695-17c78889567d] [UpdateTaskStatus] Task: c80f51a9-818f-4825-9695-17c78889567d, State: SUCCESS
I20251129 18:38:12.350629 30725 scheduler_service_impl.cpp:106] [ReqID:UPD-f8735dfd-6d56-4f23-9ef0-57abaadb6605] [UpdateTaskStatus] Task: f8735dfd-6d56-4f23-9ef0-57abaadb6605, State: SUCCESS
I20251129 18:38:12.350670 30726 scheduler_service_impl.cpp:106] [ReqID:UPD-a6010ba8-462d-48ca-8688-5f818bae6605] [UpdateTaskStatus] Task: a6010ba8-462d-48ca-8688-5f818bae6605, State: SUCCESS
I20251129 18:38:12.353942 30723 scheduler_service_impl.cpp:106] [ReqID:UPD-62631ac9-cd52-4349-a9fa-bb1928d32814] [UpdateTaskStatus] Task: 62631ac9-cd52-4349-a9fa-bb1928d32814, State: SUCCESS
I20251129 18:38:12.831965 29170 scheduler_loop.cpp:163] [ReqID:DISP-500df2b4-7da2-4f95-8591-04eeac332842] Successfully dispatched task 500df2b4-7da2-4f95-8591-04eeac332842 to worker-01
I20251129 18:38:12.831985 30726 scheduler_service_impl.cpp:106] [ReqID:UPD-500df2b4-7da2-4f95-8591-04eeac332842] [UpdateTaskStatus] Task: 500df2b4-7da2-4f95-8591-04eeac332842, State: SUCCESS
I20251129 18:38:12.861498 29165 scheduler_loop.cpp:163] [ReqID:DISP-af0982c9-a93c-48a0-9ea6-01a1c3e4307a] Successfully dispatched task af0982c9-a93c-48a0-9ea6-01a1c3e4307a to worker-01
I20251129 18:38:12.861622 29166 scheduler_loop.cpp:163] [ReqID:DISP-b92ec2fe-4338-4063-bf1e-ff7667d93028] Successfully dispatched task b92ec2fe-4338-4063-bf1e-ff7667d93028 to worker-01
I20251129 18:38:12.861653 29164 scheduler_loop.cpp:163] [ReqID:DISP-f941c485-ec1a-45e7-a15f-afc1ec53ac6f] Successfully dispatched task f941c485-ec1a-45e7-a15f-afc1ec53ac6f to worker-01
I20251129 18:38:12.861665 30727 scheduler_service_impl.cpp:106] [ReqID:UPD-f941c485-ec1a-45e7-a15f-afc1ec53ac6f] [UpdateTaskStatus] Task: f941c485-ec1a-45e7-a15f-afc1ec53ac6f, State: SUCCESS
I20251129 18:38:12.861687 29167 scheduler_loop.cpp:163] [ReqID:DISP-7cd0fa2d-a1f5-46c1-9d0d-1e6b7a58f1ee] Successfully dispatched task 7cd0fa2d-a1f5-46c1-9d0d-1e6b7a58f1ee to worker-01
I20251129 18:38:12.862267 29163 scheduler_loop.cpp:163] [ReqID:DISP-95800e6b-32be-4551-94a3-c69276a26845] Successfully dispatched task 95800e6b-32be-4551-94a3-c69276a26845 to worker-01
I20251129 18:38:12.861835 30739 scheduler_service_impl.cpp:106] [ReqID:UPD-68cbb762-3112-4180-9a0c-1d9df9b9ff0d] [UpdateTaskStatus] Task: 68cbb762-3112-4180-9a0c-1d9df9b9ff0d, State: SUCCESS
I20251129 18:38:12.862030 29169 scheduler_loop.cpp:163] [ReqID:DISP-3b12cad6-8b1b-438d-ad08-7183d97721ac] Successfully dispatched task 3b12cad6-8b1b-438d-ad08-7183d97721ac to worker-01
I20251129 18:38:12.861750 29168 scheduler_loop.cpp:163] [ReqID:DISP-68cbb762-3112-4180-9a0c-1d9df9b9ff0d] Successfully dispatched task 68cbb762-3112-4180-9a0c-1d9df9b9ff0d to worker-01
I20251129 18:38:12.862552 30726 scheduler_service_impl.cpp:106] [ReqID:UPD-af0982c9-a93c-48a0-9ea6-01a1c3e4307a] [UpdateTaskStatus] Task: af0982c9-a93c-48a0-9ea6-01a1c3e4307a, State: SUCCESS
I20251129 18:38:12.862614 30740 scheduler_service_impl.cpp:106] [ReqID:UPD-7cd0fa2d-a1f5-46c1-9d0d-1e6b7a58f1ee] [UpdateTaskStatus] Task: 7cd0fa2d-a1f5-46c1-9d0d-1e6b7a58f1ee, State: SUCCESS
I20251129 18:38:12.862887 29170 scheduler_loop.cpp:163] [ReqID:DISP-1f2cead7-6a8c-4ce8-989b-2635d74bd847] Successfully dispatched task 1f2cead7-6a8c-4ce8-989b-2635d74bd847 to worker-01
I20251129 18:38:12.865329 29165 scheduler_loop.cpp:163] [ReqID:DISP-34db2569-05ae-43c3-b1bf-b5dac7f38442] Successfully dispatched task 34db2569-05ae-43c3-b1bf-b5dac7f38442 to worker-01
I20251129 18:38:12.866354 30740 scheduler_service_impl.cpp:106] [ReqID:UPD-3b12cad6-8b1b-438d-ad08-7183d97721ac] [UpdateTaskStatus] Task: 3b12cad6-8b1b-438d-ad08-7183d97721ac, State: SUCCESS
I20251129 18:38:12.866391 30741 scheduler_service_impl.cpp:106] [ReqID:UPD-95800e6b-32be-4551-94a3-c69276a26845] [UpdateTaskStatus] Task: 95800e6b-32be-4551-94a3-c69276a26845, State: SUCCESS
I20251129 18:38:12.866461 30742 scheduler_service_impl.cpp:106] [ReqID:UPD-b92ec2fe-4338-4063-bf1e-ff7667d93028] [UpdateTaskStatus] Task: b92ec2fe-4338-4063-bf1e-ff7667d93028, State: SUCCESS
I20251129 18:38:12.866508 30743 scheduler_service_impl.cpp:106] [ReqID:UPD-1f2cead7-6a8c-4ce8-989b-2635d74bd847] [UpdateTaskStatus] Task: 1f2cead7-6a8c-4ce8-989b-2635d74bd847, State: SUCCESS
I20251129 18:38:12.869940 30740 scheduler_service_impl.cpp:106] [ReqID:UPD-34db2569-05ae-43c3-b1bf-b5dac7f38442] [UpdateTaskStatus] Task: 34db2569-05ae-43c3-b1bf-b5dac7f38442, State: SUCCESS
I20251129 18:38:13.329952 29169 scheduler_loop.cpp:163] [ReqID:DISP-df6dbf82-fb92-420a-805b-2ec831bd5cca] Successfully dispatched task df6dbf82-fb92-420a-805b-2ec831bd5cca to worker-01
I20251129 18:38:13.330291 30744 scheduler_service_impl.cpp:106] [ReqID:UPD-df6dbf82-fb92-420a-805b-2ec831bd5cca] [UpdateTaskStatus] Task: df6dbf82-fb92-420a-805b-2ec831bd5cca, State: SUCCESS
I20251129 18:38:13.331284 30741 scheduler_service_impl.cpp:106] [ReqID:UPD-e7c77172-5b37-47d0-b14b-1cd3ee70048d] [UpdateTaskStatus] Task: e7c77172-5b37-47d0-b14b-1cd3ee70048d, State: SUCCESS
I20251129 18:38:13.331808 30755 scheduler_service_impl.cpp:106] [ReqID:UPD-78444ada-2747-430a-a03c-8f418fbf8e8d] [UpdateTaskStatus] Task: 78444ada-2747-430a-a03c-8f418fbf8e8d, State: SUCCESS
I20251129 18:38:13.331977 30757 scheduler_service_impl.cpp:106] [ReqID:UPD-50036e9e-adec-40da-ab3d-f313c6b43d51] [UpdateTaskStatus] Task: 50036e9e-adec-40da-ab3d-f313c6b43d51, State: SUCCESS
I20251129 18:38:13.332340 29164 scheduler_loop.cpp:163] [ReqID:DISP-e7c77172-5b37-47d0-b14b-1cd3ee70048d] Successfully dispatched task e7c77172-5b37-47d0-b14b-1cd3ee70048d to worker-01
I20251129 18:38:13.332340 29166 scheduler_loop.cpp:163] [ReqID:DISP-78444ada-2747-430a-a03c-8f418fbf8e8d] Successfully dispatched task 78444ada-2747-430a-a03c-8f418fbf8e8d to worker-01
I20251129 18:38:13.332441 29163 scheduler_loop.cpp:163] [ReqID:DISP-25fb8eda-60da-42b6-8557-d9ddc4b5ef89] Successfully dispatched task 25fb8eda-60da-42b6-8557-d9ddc4b5ef89 to worker-01
I20251129 18:38:13.332463 29168 scheduler_loop.cpp:163] [ReqID:DISP-50036e9e-adec-40da-ab3d-f313c6b43d51] Successfully dispatched task 50036e9e-adec-40da-ab3d-f313c6b43d51 to worker-01
I20251129 18:38:13.332485 29170 scheduler_loop.cpp:163] [ReqID:DISP-5d3a3904-3797-471f-9b5e-407a18633188] Successfully dispatched task 5d3a3904-3797-471f-9b5e-407a18633188 to worker-01
I20251129 18:38:13.332350 29165 scheduler_loop.cpp:163] [ReqID:DISP-9da85f36-7893-47db-b2f3-0c4b6a7fa0f6] Successfully dispatched task 9da85f36-7893-47db-b2f3-0c4b6a7fa0f6 to worker-01
I20251129 18:38:13.332508 29167 scheduler_loop.cpp:163] [ReqID:DISP-2d19048f-584c-49ef-9507-fac5446c3d30] Successfully dispatched task 2d19048f-584c-49ef-9507-fac5446c3d30 to worker-01
I20251129 18:38:13.333639 29169 scheduler_loop.cpp:163] [ReqID:DISP-81cfa862-b0bf-40d0-a854-f5f60bd5dff9] Successfully dispatched task 81cfa862-b0bf-40d0-a854-f5f60bd5dff9 to worker-01
I20251129 18:38:13.334619 30744 scheduler_service_impl.cpp:106] [ReqID:UPD-25fb8eda-60da-42b6-8557-d9ddc4b5ef89] [UpdateTaskStatus] Task: 25fb8eda-60da-42b6-8557-d9ddc4b5ef89, State: SUCCESS
I20251129 18:38:13.335644 30757 scheduler_service_impl.cpp:106] [ReqID:UPD-5d3a3904-3797-471f-9b5e-407a18633188] [UpdateTaskStatus] Task: 5d3a3904-3797-471f-9b5e-407a18633188, State: SUCCESS
I20251129 18:38:13.335893 29164 scheduler_loop.cpp:163] [ReqID:DISP-37efd615-b163-4a2e-bd67-da60a5f448a0] Successfully dispatched task 37efd615-b163-4a2e-bd67-da60a5f448a0 to worker-01
I20251129 18:38:13.335909 30758 scheduler_service_impl.cpp:106] [ReqID:UPD-2d19048f-584c-49ef-9507-fac5446c3d30] [UpdateTaskStatus] Task: 2d19048f-584c-49ef-9507-fac5446c3d30, State: SUCCESS
I20251129 18:38:13.336136 30759 scheduler_service_impl.cpp:106] [ReqID:UPD-9da85f36-7893-47db-b2f3-0c4b6a7fa0f6] [UpdateTaskStatus] Task: 9da85f36-7893-47db-b2f3-0c4b6a7fa0f6, State: SUCCESS
I20251129 18:38:13.338768 30744 scheduler_service_impl.cpp:106] [ReqID:UPD-81cfa862-b0bf-40d0-a854-f5f60bd5dff9] [UpdateTaskStatus] Task: 81cfa862-b0bf-40d0-a854-f5f60bd5dff9, State: SUCCESS
I20251129 18:38:13.339876 30758 scheduler_service_impl.cpp:106] [ReqID:UPD-37efd615-b163-4a2e-bd67-da60a5f448a0] [UpdateTaskStatus] Task: 37efd615-b163-4a2e-bd67-da60a5f448a0, State: SUCCESS
I20251129 18:38:13.832790 29166 scheduler_loop.cpp:163] [ReqID:DISP-b699164c-3139-4e26-b7fe-2d042cf4968f] Successfully dispatched task b699164c-3139-4e26-b7fe-2d042cf4968f to worker-01
I20251129 18:38:13.833091 29170 scheduler_loop.cpp:163] [ReqID:DISP-ca5343bf-3461-485c-ab20-55b20ec8d43b] Successfully dispatched task ca5343bf-3461-485c-ab20-55b20ec8d43b to worker-01
I20251129 18:38:13.832806 29163 scheduler_loop.cpp:163] [ReqID:DISP-52102e89-6afd-4a08-8f0f-9613ebdddf11] Successfully dispatched task 52102e89-6afd-4a08-8f0f-9613ebdddf11 to worker-01
I20251129 18:38:13.833101 30744 scheduler_service_impl.cpp:106] [ReqID:UPD-b699164c-3139-4e26-b7fe-2d042cf4968f] [UpdateTaskStatus] Task: b699164c-3139-4e26-b7fe-2d042cf4968f, State: SUCCESS
I20251129 18:38:13.833165 30760 scheduler_service_impl.cpp:106] [ReqID:UPD-52102e89-6afd-4a08-8f0f-9613ebdddf11] [UpdateTaskStatus] Task: 52102e89-6afd-4a08-8f0f-9613ebdddf11, State: SUCCESS
I20251129 18:38:13.833213 30763 scheduler_service_impl.cpp:106] [ReqID:UPD-ca5343bf-3461-485c-ab20-55b20ec8d43b] [UpdateTaskStatus] Task: ca5343bf-3461-485c-ab20-55b20ec8d43b, State: SUCCESS
I20251129 18:38:13.840373 29169 scheduler_loop.cpp:163] [ReqID:DISP-225a06e8-fcea-4203-9be7-185be96e5be9] Successfully dispatched task 225a06e8-fcea-4203-9be7-185be96e5be9 to worker-01
I20251129 18:38:13.840397 29168 scheduler_loop.cpp:163] [ReqID:DISP-e85f0b8c-11e6-48a5-8f50-ab19615463ac] Successfully dispatched task e85f0b8c-11e6-48a5-8f50-ab19615463ac to worker-01
I20251129 18:38:13.840423 29165 scheduler_loop.cpp:163] [ReqID:DISP-3151af60-73e5-4b53-b23a-92cd453988f8] Successfully dispatched task 3151af60-73e5-4b53-b23a-92cd453988f8 to worker-01
I20251129 18:38:13.840438 29164 scheduler_loop.cpp:163] [ReqID:DISP-7fe8c0c8-43af-4284-96d2-1b7603232e4a] Successfully dispatched task 7fe8c0c8-43af-4284-96d2-1b7603232e4a to worker-01
I20251129 18:38:13.840628 29167 scheduler_loop.cpp:163] [ReqID:DISP-709ad74c-2d4b-4c86-b6b7-42bb05c56ab2] Successfully dispatched task 709ad74c-2d4b-4c86-b6b7-42bb05c56ab2 to worker-01
I20251129 18:38:13.840965 30764 scheduler_service_impl.cpp:106] [ReqID:UPD-7fe8c0c8-43af-4284-96d2-1b7603232e4a] [UpdateTaskStatus] Task: 7fe8c0c8-43af-4284-96d2-1b7603232e4a, State: SUCCESS
I20251129 18:38:13.841907 29166 scheduler_loop.cpp:163] [ReqID:DISP-3ff51980-ec63-410b-863a-715f59c6a37a] Successfully dispatched task 3ff51980-ec63-410b-863a-715f59c6a37a to worker-01
I20251129 18:38:13.841934 29170 scheduler_loop.cpp:163] [ReqID:DISP-0f55a836-0010-41a0-b1cb-fd9cc22c3e63] Successfully dispatched task 0f55a836-0010-41a0-b1cb-fd9cc22c3e63 to worker-01
I20251129 18:38:13.842029 30760 scheduler_service_impl.cpp:106] [ReqID:UPD-3151af60-73e5-4b53-b23a-92cd453988f8] [UpdateTaskStatus] Task: 3151af60-73e5-4b53-b23a-92cd453988f8, State: SUCCESS
I20251129 18:38:13.842103 30744 scheduler_service_impl.cpp:106] [ReqID:UPD-e85f0b8c-11e6-48a5-8f50-ab19615463ac] [UpdateTaskStatus] Task: e85f0b8c-11e6-48a5-8f50-ab19615463ac, State: SUCCESS
I20251129 18:38:13.842142 30770 scheduler_service_impl.cpp:106] [ReqID:UPD-225a06e8-fcea-4203-9be7-185be96e5be9] [UpdateTaskStatus] Task: 225a06e8-fcea-4203-9be7-185be96e5be9, State: SUCCESS
I20251129 18:38:13.845613 30764 scheduler_service_impl.cpp:106] [ReqID:UPD-709ad74c-2d4b-4c86-b6b7-42bb05c56ab2] [UpdateTaskStatus] Task: 709ad74c-2d4b-4c86-b6b7-42bb05c56ab2, State: SUCCESS
I20251129 18:38:13.846462 30770 scheduler_service_impl.cpp:106] [ReqID:UPD-0f55a836-0010-41a0-b1cb-fd9cc22c3e63] [UpdateTaskStatus] Task: 0f55a836-0010-41a0-b1cb-fd9cc22c3e63, State: SUCCESS
I20251129 18:38:13.846637 30771 scheduler_service_impl.cpp:106] [ReqID:UPD-3ff51980-ec63-410b-863a-715f59c6a37a] [UpdateTaskStatus] Task: 3ff51980-ec63-410b-863a-715f59c6a37a, State: SUCCESS
I20251129 18:38:14.334834 29166 scheduler_loop.cpp:163] [ReqID:DISP-bd1d7072-fe2a-451e-853d-123608d4c725] Successfully dispatched task bd1d7072-fe2a-451e-853d-123608d4c725 to worker-01
I20251129 18:38:14.335088 30772 scheduler_service_impl.cpp:106] [ReqID:UPD-bd1d7072-fe2a-451e-853d-123608d4c725] [UpdateTaskStatus] Task: bd1d7072-fe2a-451e-853d-123608d4c725, State: SUCCESS
I20251129 18:38:14.335140 29169 scheduler_loop.cpp:163] [ReqID:DISP-01c4b3e8-f6f0-4f3e-88dc-227ce8d9893e] Successfully dispatched task 01c4b3e8-f6f0-4f3e-88dc-227ce8d9893e to worker-01
I20251129 18:38:14.335610 29165 scheduler_loop.cpp:163] [ReqID:DISP-cbbb8716-bbb2-4327-aedd-9389ac0b50aa] Successfully dispatched task cbbb8716-bbb2-4327-aedd-9389ac0b50aa to worker-01
I20251129 18:38:14.335690 30764 scheduler_service_impl.cpp:106] [ReqID:UPD-01c4b3e8-f6f0-4f3e-88dc-227ce8d9893e] [UpdateTaskStatus] Task: 01c4b3e8-f6f0-4f3e-88dc-227ce8d9893e, State: SUCCESS
I20251129 18:38:14.335778 30774 scheduler_service_impl.cpp:106] [ReqID:UPD-cbbb8716-bbb2-4327-aedd-9389ac0b50aa] [UpdateTaskStatus] Task: cbbb8716-bbb2-4327-aedd-9389ac0b50aa, State: SUCCESS
I20251129 18:38:14.335879 29164 scheduler_loop.cpp:163] [ReqID:DISP-0736f99b-619a-42be-8269-9eb4efb1748b] Successfully dispatched task 0736f99b-619a-42be-8269-9eb4efb1748b to worker-01
I20251129 18:38:14.335881 29170 scheduler_loop.cpp:163] [ReqID:DISP-e71344c5-a50c-4a6c-a18c-b189213017a8] Successfully dispatched task e71344c5-a50c-4a6c-a18c-b189213017a8 to worker-01
I20251129 18:38:14.335896 29167 scheduler_loop.cpp:163] [ReqID:DISP-0f3cff00-5304-452d-b660-7e8b4b2961f4] Successfully dispatched task 0f3cff00-5304-452d-b660-7e8b4b2961f4 to worker-01
I20251129 18:38:14.336632 29163 scheduler_loop.cpp:163] [ReqID:DISP-86628a4a-0fb3-4414-850f-5141cf67e1d1] Successfully dispatched task 86628a4a-0fb3-4414-850f-5141cf67e1d1 to worker-01
I20251129 18:38:14.336723 30777 scheduler_service_impl.cpp:106] [ReqID:UPD-0736f99b-619a-42be-8269-9eb4efb1748b] [UpdateTaskStatus] Task: 0736f99b-619a-42be-8269-9eb4efb1748b, State: SUCCESS
I20251129 18:38:14.336871 29168 scheduler_loop.cpp:163] [ReqID:DISP-73e06260-4f66-4349-a5a9-ca8db4bf6789] Successfully dispatched task 73e06260-4f66-4349-a5a9-ca8db4bf6789 to worker-01
I20251129 18:38:14.338551 29169 scheduler_loop.cpp:163] [ReqID:DISP-2e2c97a4-a292-4235-bbff-847c383b558c] Successfully dispatched task 2e2c97a4-a292-4235-bbff-847c383b558c to worker-01
I20251129 18:38:14.339366 30764 scheduler_service_impl.cpp:106] [ReqID:UPD-0f3cff00-5304-452d-b660-7e8b4b2961f4] [UpdateTaskStatus] Task: 0f3cff00-5304-452d-b660-7e8b4b2961f4, State: SUCCESS
I20251129 18:38:14.339417 30778 scheduler_service_impl.cpp:106] [ReqID:UPD-e71344c5-a50c-4a6c-a18c-b189213017a8] [UpdateTaskStatus] Task: e71344c5-a50c-4a6c-a18c-b189213017a8, State: SUCCESS
I20251129 18:38:14.339510 29166 scheduler_loop.cpp:163] [ReqID:DISP-d358e600-2dbc-4124-b373-55b16b76bbfd] Successfully dispatched task d358e600-2dbc-4124-b373-55b16b76bbfd to worker-01
I20251129 18:38:14.339643 30779 scheduler_service_impl.cpp:106] [ReqID:UPD-73e06260-4f66-4349-a5a9-ca8db4bf6789] [UpdateTaskStatus] Task: 73e06260-4f66-4349-a5a9-ca8db4bf6789, State: SUCCESS
I20251129 18:38:14.340301 30777 scheduler_service_impl.cpp:106] [ReqID:UPD-86628a4a-0fb3-4414-850f-5141cf67e1d1] [UpdateTaskStatus] Task: 86628a4a-0fb3-4414-850f-5141cf67e1d1, State: SUCCESS
I20251129 18:38:14.342365 30764 scheduler_service_impl.cpp:106] [ReqID:UPD-2e2c97a4-a292-4235-bbff-847c383b558c] [UpdateTaskStatus] Task: 2e2c97a4-a292-4235-bbff-847c383b558c, State: SUCCESS
I20251129 18:38:14.343422 30777 scheduler_service_impl.cpp:106] [ReqID:UPD-d358e600-2dbc-4124-b373-55b16b76bbfd] [UpdateTaskStatus] Task: d358e600-2dbc-4124-b373-55b16b76bbfd, State: SUCCESS
I20251129 18:38:14.836176 29169 scheduler_loop.cpp:163] [ReqID:DISP-b923fc2f-5b19-4547-b1d9-e49df9e07183] Successfully dispatched task b923fc2f-5b19-4547-b1d9-e49df9e07183 to worker-01
I20251129 18:38:14.836810 30764 scheduler_service_impl.cpp:106] [ReqID:UPD-b923fc2f-5b19-4547-b1d9-e49df9e07183] [UpdateTaskStatus] Task: b923fc2f-5b19-4547-b1d9-e49df9e07183, State: SUCCESS
I20251129 18:38:14.837392 30780 scheduler_service_impl.cpp:106] [ReqID:UPD-0e6990aa-b8db-494a-8ddf-59a38cf44593] [UpdateTaskStatus] Task: 0e6990aa-b8db-494a-8ddf-59a38cf44593, State: SUCCESS
I20251129 18:38:14.837663 30802 scheduler_service_impl.cpp:106] [ReqID:UPD-b7f4edc5-ddd0-4cd5-a690-f858791b8f0b] [UpdateTaskStatus] Task: b7f4edc5-ddd0-4cd5-a690-f858791b8f0b, State: SUCCESS
I20251129 18:38:14.837783 30803 scheduler_service_impl.cpp:106] [ReqID:UPD-99e76257-2d34-4a54-8ba3-2270df183759] [UpdateTaskStatus] Task: 99e76257-2d34-4a54-8ba3-2270df183759, State: SUCCESS
I20251129 18:38:14.837803 29165 scheduler_loop.cpp:163] [ReqID:DISP-99e76257-2d34-4a54-8ba3-2270df183759] Successfully dispatched task 99e76257-2d34-4a54-8ba3-2270df183759 to worker-01
I20251129 18:38:14.837919 29164 scheduler_loop.cpp:163] [ReqID:DISP-0e6990aa-b8db-494a-8ddf-59a38cf44593] Successfully dispatched task 0e6990aa-b8db-494a-8ddf-59a38cf44593 to worker-01
I20251129 18:38:14.837709 29167 scheduler_loop.cpp:163] [ReqID:DISP-7fb2fa0d-f37b-437e-a4c9-726871a080ca] Successfully dispatched task 7fb2fa0d-f37b-437e-a4c9-726871a080ca to worker-01
I20251129 18:38:14.837980 29170 scheduler_loop.cpp:163] [ReqID:DISP-b7f4edc5-ddd0-4cd5-a690-f858791b8f0b] Successfully dispatched task b7f4edc5-ddd0-4cd5-a690-f858791b8f0b to worker-01
I20251129 18:38:14.838014 29168 scheduler_loop.cpp:163] [ReqID:DISP-27083871-e313-445b-9f09-868c44ba0774] Successfully dispatched task 27083871-e313-445b-9f09-868c44ba0774 to worker-01
I20251129 18:38:14.838215 29166 scheduler_loop.cpp:163] [ReqID:DISP-2c825d62-7d4c-4c15-9eb9-181100837e12] Successfully dispatched task 2c825d62-7d4c-4c15-9eb9-181100837e12 to worker-01
I20251129 18:38:14.838225 29163 scheduler_loop.cpp:163] [ReqID:DISP-75a95624-7016-4b5f-a6ad-560a6c979cf8] Successfully dispatched task 75a95624-7016-4b5f-a6ad-560a6c979cf8 to worker-01
I20251129 18:38:14.840340 29169 scheduler_loop.cpp:163] [ReqID:DISP-83c8335f-d056-49e4-af65-2f160b184368] Successfully dispatched task 83c8335f-d056-49e4-af65-2f160b184368 to worker-01
I20251129 18:38:14.840632 30804 scheduler_service_impl.cpp:106] [ReqID:UPD-27083871-e313-445b-9f09-868c44ba0774] [UpdateTaskStatus] Task: 27083871-e313-445b-9f09-868c44ba0774, State: SUCCESS
I20251129 18:38:14.841722 30803 scheduler_service_impl.cpp:106] [ReqID:UPD-2c825d62-7d4c-4c15-9eb9-181100837e12] [UpdateTaskStatus] Task: 2c825d62-7d4c-4c15-9eb9-181100837e12, State: SUCCESS
I20251129 18:38:14.842217 30764 scheduler_service_impl.cpp:106] [ReqID:UPD-7fb2fa0d-f37b-437e-a4c9-726871a080ca] [UpdateTaskStatus] Task: 7fb2fa0d-f37b-437e-a4c9-726871a080ca, State: SUCCESS
I20251129 18:38:14.842226 29165 scheduler_loop.cpp:163] [ReqID:DISP-e78f16e9-a5f8-420f-8490-516746f1a1ba] Successfully dispatched task e78f16e9-a5f8-420f-8490-516746f1a1ba to worker-01
I20251129 18:38:14.842330 30805 scheduler_service_impl.cpp:106] [ReqID:UPD-75a95624-7016-4b5f-a6ad-560a6c979cf8] [UpdateTaskStatus] Task: 75a95624-7016-4b5f-a6ad-560a6c979cf8, State: SUCCESS
I20251129 18:38:14.845029 30804 scheduler_service_impl.cpp:106] [ReqID:UPD-83c8335f-d056-49e4-af65-2f160b184368] [UpdateTaskStatus] Task: 83c8335f-d056-49e4-af65-2f160b184368, State: SUCCESS
I20251129 18:38:14.845803 30803 scheduler_service_impl.cpp:106] [ReqID:UPD-e78f16e9-a5f8-420f-8490-516746f1a1ba] [UpdateTaskStatus] Task: e78f16e9-a5f8-420f-8490-516746f1a1ba, State: SUCCESS
I20251129 18:38:15.342996 29165 scheduler_loop.cpp:163] [ReqID:DISP-f3ad05d9-db6d-4d1d-aa77-d374623b979b] Successfully dispatched task f3ad05d9-db6d-4d1d-aa77-d374623b979b to worker-01
I20251129 18:38:15.343066 30804 scheduler_service_impl.cpp:106] [ReqID:UPD-f3ad05d9-db6d-4d1d-aa77-d374623b979b] [UpdateTaskStatus] Task: f3ad05d9-db6d-4d1d-aa77-d374623b979b, State: SUCCESS
I20251129 18:38:15.344364 29164 scheduler_loop.cpp:163] [ReqID:DISP-08cae974-9819-447a-9c6a-0ef344b1a7f8] Successfully dispatched task 08cae974-9819-447a-9c6a-0ef344b1a7f8 to worker-01
I20251129 18:38:15.344473 29166 scheduler_loop.cpp:163] [ReqID:DISP-8cc11869-6be3-4a9e-9457-6aa3a8a77fb4] Successfully dispatched task 8cc11869-6be3-4a9e-9457-6aa3a8a77fb4 to worker-01
I20251129 18:38:15.344482 29170 scheduler_loop.cpp:163] [ReqID:DISP-4aedb096-2256-46eb-ab63-c98c60c237af] Successfully dispatched task 4aedb096-2256-46eb-ab63-c98c60c237af to worker-01
I20251129 18:38:15.344537 29169 scheduler_loop.cpp:163] [ReqID:DISP-fd90852f-5eeb-4ca8-bd0a-272cc6255666] Successfully dispatched task fd90852f-5eeb-4ca8-bd0a-272cc6255666 to worker-01
I20251129 18:38:15.344668 29167 scheduler_loop.cpp:163] [ReqID:DISP-cb4fba18-fa93-48e2-b158-37d22ca2abd9] Successfully dispatched task cb4fba18-fa93-48e2-b158-37d22ca2abd9 to worker-01
I20251129 18:38:15.344681 29163 scheduler_loop.cpp:163] [ReqID:DISP-72bcb279-c98a-4c22-a46f-2ed6a35a9a73] Successfully dispatched task 72bcb279-c98a-4c22-a46f-2ed6a35a9a73 to worker-01
I20251129 18:38:15.344699 29168 scheduler_loop.cpp:163] [ReqID:DISP-d32e7894-6013-4037-a45e-eb414289deae] Successfully dispatched task d32e7894-6013-4037-a45e-eb414289deae to worker-01
I20251129 18:38:15.344825 30806 scheduler_service_impl.cpp:106] [ReqID:UPD-08cae974-9819-447a-9c6a-0ef344b1a7f8] [UpdateTaskStatus] Task: 08cae974-9819-447a-9c6a-0ef344b1a7f8, State: SUCCESS
I20251129 18:38:15.344859 30809 scheduler_service_impl.cpp:106] [ReqID:UPD-8cc11869-6be3-4a9e-9457-6aa3a8a77fb4] [UpdateTaskStatus] Task: 8cc11869-6be3-4a9e-9457-6aa3a8a77fb4, State: SUCCESS
I20251129 18:38:15.344909 30810 scheduler_service_impl.cpp:106] [ReqID:UPD-4aedb096-2256-46eb-ab63-c98c60c237af] [UpdateTaskStatus] Task: 4aedb096-2256-46eb-ab63-c98c60c237af, State: SUCCESS
I20251129 18:38:15.347239 29165 scheduler_loop.cpp:163] [ReqID:DISP-f636abc8-b23b-44f7-a804-1abea75242d2] Successfully dispatched task f636abc8-b23b-44f7-a804-1abea75242d2 to worker-01
I20251129 18:38:15.348011 30804 scheduler_service_impl.cpp:106] [ReqID:UPD-fd90852f-5eeb-4ca8-bd0a-272cc6255666] [UpdateTaskStatus] Task: fd90852f-5eeb-4ca8-bd0a-272cc6255666, State: SUCCESS
I20251129 18:38:15.348074 29164 scheduler_loop.cpp:163] [ReqID:DISP-7c1a6793-51a0-4906-bcae-3dfc3e942509] Successfully dispatched task 7c1a6793-51a0-4906-bcae-3dfc3e942509 to worker-01
I20251129 18:38:15.349279 30810 scheduler_service_impl.cpp:106] [ReqID:UPD-72bcb279-c98a-4c22-a46f-2ed6a35a9a73] [UpdateTaskStatus] Task: 72bcb279-c98a-4c22-a46f-2ed6a35a9a73, State: SUCCESS
I20251129 18:38:15.349380 30811 scheduler_service_impl.cpp:106] [ReqID:UPD-cb4fba18-fa93-48e2-b158-37d22ca2abd9] [UpdateTaskStatus] Task: cb4fba18-fa93-48e2-b158-37d22ca2abd9, State: SUCCESS
I20251129 18:38:15.349448 30812 scheduler_service_impl.cpp:106] [ReqID:UPD-d32e7894-6013-4037-a45e-eb414289deae] [UpdateTaskStatus] Task: d32e7894-6013-4037-a45e-eb414289deae, State: SUCCESS
I20251129 18:38:15.351301 30804 scheduler_service_impl.cpp:106] [ReqID:UPD-f636abc8-b23b-44f7-a804-1abea75242d2] [UpdateTaskStatus] Task: f636abc8-b23b-44f7-a804-1abea75242d2, State: SUCCESS
I20251129 18:38:15.352500 30812 scheduler_service_impl.cpp:106] [ReqID:UPD-7c1a6793-51a0-4906-bcae-3dfc3e942509] [UpdateTaskStatus] Task: 7c1a6793-51a0-4906-bcae-3dfc3e942509, State: SUCCESS
I20251129 18:38:15.844408 29166 scheduler_loop.cpp:163] [ReqID:DISP-51ff4375-decf-426e-bdac-a7f0b3439fc7] Successfully dispatched task 51ff4375-decf-426e-bdac-a7f0b3439fc7 to worker-01
I20251129 18:38:15.844489 30811 scheduler_service_impl.cpp:106] [ReqID:UPD-51ff4375-decf-426e-bdac-a7f0b3439fc7] [UpdateTaskStatus] Task: 51ff4375-decf-426e-bdac-a7f0b3439fc7, State: SUCCESS
I20251129 18:38:15.861223 29164 scheduler_loop.cpp:163] [ReqID:DISP-d81eeb20-37b0-4ff5-a340-309f587c7a84] Successfully dispatched task d81eeb20-37b0-4ff5-a340-309f587c7a84 to worker-01
I20251129 18:38:15.861244 29168 scheduler_loop.cpp:163] [ReqID:DISP-1e93a914-3aa3-4b6b-a413-c3564de3edc2] Successfully dispatched task 1e93a914-3aa3-4b6b-a413-c3564de3edc2 to worker-01
I20251129 18:38:15.861313 29165 scheduler_loop.cpp:163] [ReqID:DISP-5f218d46-de06-44ff-8517-41b1c5b5e805] Successfully dispatched task 5f218d46-de06-44ff-8517-41b1c5b5e805 to worker-01
I20251129 18:38:15.861352 29170 scheduler_loop.cpp:163] [ReqID:DISP-5eee81ad-b37f-4523-8ccc-eab46b7ba27a] Successfully dispatched task 5eee81ad-b37f-4523-8ccc-eab46b7ba27a to worker-01
I20251129 18:38:15.861479 30813 scheduler_service_impl.cpp:106] [ReqID:UPD-d81eeb20-37b0-4ff5-a340-309f587c7a84] [UpdateTaskStatus] Task: d81eeb20-37b0-4ff5-a340-309f587c7a84, State: SUCCESS
I20251129 18:38:15.861564 30824 scheduler_service_impl.cpp:106] [ReqID:UPD-5eee81ad-b37f-4523-8ccc-eab46b7ba27a] [UpdateTaskStatus] Task: 5eee81ad-b37f-4523-8ccc-eab46b7ba27a, State: SUCCESS
I20251129 18:38:15.861670 29169 scheduler_loop.cpp:163] [ReqID:DISP-3d54434c-d4c7-45af-bc29-c707be165b54] Successfully dispatched task 3d54434c-d4c7-45af-bc29-c707be165b54 to worker-01
I20251129 18:38:15.861652 30825 scheduler_service_impl.cpp:106] [ReqID:UPD-1e93a914-3aa3-4b6b-a413-c3564de3edc2] [UpdateTaskStatus] Task: 1e93a914-3aa3-4b6b-a413-c3564de3edc2, State: SUCCESS
I20251129 18:38:15.861651 29163 scheduler_loop.cpp:163] [ReqID:DISP-9883cf69-ee84-48a0-9108-1169cefd28e7] Successfully dispatched task 9883cf69-ee84-48a0-9108-1169cefd28e7 to worker-01
I20251129 18:38:15.861657 29167 scheduler_loop.cpp:163] [ReqID:DISP-2b6ffbaf-f6ac-4f5f-aeb3-a9dd4c4ea1bf] Successfully dispatched task 2b6ffbaf-f6ac-4f5f-aeb3-a9dd4c4ea1bf to worker-01
I20251129 18:38:15.869580 30811 scheduler_service_impl.cpp:106] [ReqID:UPD-5f218d46-de06-44ff-8517-41b1c5b5e805] [UpdateTaskStatus] Task: 5f218d46-de06-44ff-8517-41b1c5b5e805, State: SUCCESS
I20251129 18:38:15.869696 29166 scheduler_loop.cpp:163] [ReqID:DISP-5a35103f-5298-4f52-a714-4cef72392662] Successfully dispatched task 5a35103f-5298-4f52-a714-4cef72392662 to worker-01
I20251129 18:38:15.870385 30813 scheduler_service_impl.cpp:106] [ReqID:UPD-3d54434c-d4c7-45af-bc29-c707be165b54] [UpdateTaskStatus] Task: 3d54434c-d4c7-45af-bc29-c707be165b54, State: SUCCESS
I20251129 18:38:15.870461 29164 scheduler_loop.cpp:163] [ReqID:DISP-e1fd1ed2-772b-4fec-8f1d-7322d6b3fadd] Successfully dispatched task e1fd1ed2-772b-4fec-8f1d-7322d6b3fadd to worker-01
I20251129 18:38:15.870566 30826 scheduler_service_impl.cpp:106] [ReqID:UPD-9883cf69-ee84-48a0-9108-1169cefd28e7] [UpdateTaskStatus] Task: 9883cf69-ee84-48a0-9108-1169cefd28e7, State: SUCCESS
I20251129 18:38:15.870612 30827 scheduler_service_impl.cpp:106] [ReqID:UPD-2b6ffbaf-f6ac-4f5f-aeb3-a9dd4c4ea1bf] [UpdateTaskStatus] Task: 2b6ffbaf-f6ac-4f5f-aeb3-a9dd4c4ea1bf, State: SUCCESS
I20251129 18:38:15.873842 30811 scheduler_service_impl.cpp:106] [ReqID:UPD-5a35103f-5298-4f52-a714-4cef72392662] [UpdateTaskStatus] Task: 5a35103f-5298-4f52-a714-4cef72392662, State: SUCCESS
I20251129 18:38:15.874718 30827 scheduler_service_impl.cpp:106] [ReqID:UPD-e1fd1ed2-772b-4fec-8f1d-7322d6b3fadd] [UpdateTaskStatus] Task: e1fd1ed2-772b-4fec-8f1d-7322d6b3fadd, State: SUCCESS
I20251129 18:38:16.346575 29167 scheduler_loop.cpp:163] [ReqID:DISP-0d88dfd9-f823-4593-bb19-c0b75f21b7f7] Successfully dispatched task 0d88dfd9-f823-4593-bb19-c0b75f21b7f7 to worker-01
I20251129 18:38:16.346791 30828 scheduler_service_impl.cpp:106] [ReqID:UPD-0d88dfd9-f823-4593-bb19-c0b75f21b7f7] [UpdateTaskStatus] Task: 0d88dfd9-f823-4593-bb19-c0b75f21b7f7, State: SUCCESS
I20251129 18:38:16.347344 29166 scheduler_loop.cpp:163] [ReqID:DISP-174f4c11-b3de-405c-ac46-1619be923ce2] Successfully dispatched task 174f4c11-b3de-405c-ac46-1619be923ce2 to worker-01
I20251129 18:38:16.347435 29164 scheduler_loop.cpp:163] [ReqID:DISP-6376ae57-4974-4237-b08c-9ae6af9a8b55] Successfully dispatched task 6376ae57-4974-4237-b08c-9ae6af9a8b55 to worker-01
I20251129 18:38:16.347707 30811 scheduler_service_impl.cpp:106] [ReqID:UPD-6376ae57-4974-4237-b08c-9ae6af9a8b55] [UpdateTaskStatus] Task: 6376ae57-4974-4237-b08c-9ae6af9a8b55, State: SUCCESS
I20251129 18:38:16.347920 29170 scheduler_loop.cpp:163] [ReqID:DISP-f4b0977d-2071-4b34-a83f-021952b9d278] Successfully dispatched task f4b0977d-2071-4b34-a83f-021952b9d278 to worker-01
I20251129 18:38:16.348009 30833 scheduler_service_impl.cpp:106] [ReqID:UPD-174f4c11-b3de-405c-ac46-1619be923ce2] [UpdateTaskStatus] Task: 174f4c11-b3de-405c-ac46-1619be923ce2, State: SUCCESS
I20251129 18:38:16.348125 30834 scheduler_service_impl.cpp:106] [ReqID:UPD-f4b0977d-2071-4b34-a83f-021952b9d278] [UpdateTaskStatus] Task: f4b0977d-2071-4b34-a83f-021952b9d278, State: SUCCESS
I20251129 18:38:16.348385 29169 scheduler_loop.cpp:163] [ReqID:DISP-98720c0b-4861-4842-b9ef-2b56e5941187] Successfully dispatched task 98720c0b-4861-4842-b9ef-2b56e5941187 to worker-01
I20251129 18:38:16.348433 29165 scheduler_loop.cpp:163] [ReqID:DISP-5fdebc4d-91c2-45ec-b357-c15e8c7332e4] Successfully dispatched task 5fdebc4d-91c2-45ec-b357-c15e8c7332e4 to worker-01
I20251129 18:38:16.348451 29163 scheduler_loop.cpp:163] [ReqID:DISP-9cee46a3-0026-4073-aae0-1c5cb11715f2] Successfully dispatched task 9cee46a3-0026-4073-aae0-1c5cb11715f2 to worker-01
I20251129 18:38:16.348464 29168 scheduler_loop.cpp:163] [ReqID:DISP-32829daf-91fb-4f51-8ac4-b167b2f551b1] Successfully dispatched task 32829daf-91fb-4f51-8ac4-b167b2f551b1 to worker-01
I20251129 18:38:16.351019 29167 scheduler_loop.cpp:163] [ReqID:DISP-3f939f35-6152-429d-b57b-28b771524a3f] Successfully dispatched task 3f939f35-6152-429d-b57b-28b771524a3f to worker-01
I20251129 18:38:16.351238 30828 scheduler_service_impl.cpp:106] [ReqID:UPD-9cee46a3-0026-4073-aae0-1c5cb11715f2] [UpdateTaskStatus] Task: 9cee46a3-0026-4073-aae0-1c5cb11715f2, State: SUCCESS
I20251129 18:38:16.351357 29166 scheduler_loop.cpp:163] [ReqID:DISP-1cecf606-d070-4db7-9fa1-4dbb5f3a1417] Successfully dispatched task 1cecf606-d070-4db7-9fa1-4dbb5f3a1417 to worker-01
I20251129 18:38:16.354612 30833 scheduler_service_impl.cpp:106] [ReqID:UPD-98720c0b-4861-4842-b9ef-2b56e5941187] [UpdateTaskStatus] Task: 98720c0b-4861-4842-b9ef-2b56e5941187, State: SUCCESS
I20251129 18:38:16.354768 30835 scheduler_service_impl.cpp:106] [ReqID:UPD-32829daf-91fb-4f51-8ac4-b167b2f551b1] [UpdateTaskStatus] Task: 32829daf-91fb-4f51-8ac4-b167b2f551b1, State: SUCCESS
I20251129 18:38:16.354817 30828 scheduler_service_impl.cpp:106] [ReqID:UPD-5fdebc4d-91c2-45ec-b357-c15e8c7332e4] [UpdateTaskStatus] Task: 5fdebc4d-91c2-45ec-b357-c15e8c7332e4, State: SUCCESS
I20251129 18:38:16.355584 30836 scheduler_service_impl.cpp:106] [ReqID:UPD-3f939f35-6152-429d-b57b-28b771524a3f] [UpdateTaskStatus] Task: 3f939f35-6152-429d-b57b-28b771524a3f, State: SUCCESS
I20251129 18:38:16.358342 30833 scheduler_service_impl.cpp:106] [ReqID:UPD-1cecf606-d070-4db7-9fa1-4dbb5f3a1417] [UpdateTaskStatus] Task: 1cecf606-d070-4db7-9fa1-4dbb5f3a1417, State: SUCCESS
I20251129 18:38:16.847126 29170 scheduler_loop.cpp:163] [ReqID:DISP-4b22dadc-2abf-465a-bad3-0bf5833750ca] Successfully dispatched task 4b22dadc-2abf-465a-bad3-0bf5833750ca to worker-01
I20251129 18:38:16.847168 30837 scheduler_service_impl.cpp:106] [ReqID:UPD-4b22dadc-2abf-465a-bad3-0bf5833750ca] [UpdateTaskStatus] Task: 4b22dadc-2abf-465a-bad3-0bf5833750ca, State: SUCCESS
I20251129 18:38:16.859555 29166 scheduler_loop.cpp:163] [ReqID:DISP-18a50cb1-7efa-4ea6-ad2e-0e4956dd4170] Successfully dispatched task 18a50cb1-7efa-4ea6-ad2e-0e4956dd4170 to worker-01
I20251129 18:38:16.859654 29165 scheduler_loop.cpp:163] [ReqID:DISP-01c9572c-8256-48b3-8f20-97b53e98a0ca] Successfully dispatched task 01c9572c-8256-48b3-8f20-97b53e98a0ca to worker-01
I20251129 18:38:16.859959 30835 scheduler_service_impl.cpp:106] [ReqID:UPD-18a50cb1-7efa-4ea6-ad2e-0e4956dd4170] [UpdateTaskStatus] Task: 18a50cb1-7efa-4ea6-ad2e-0e4956dd4170, State: SUCCESS
I20251129 18:38:16.860059 30837 scheduler_service_impl.cpp:106] [ReqID:UPD-01c9572c-8256-48b3-8f20-97b53e98a0ca] [UpdateTaskStatus] Task: 01c9572c-8256-48b3-8f20-97b53e98a0ca, State: SUCCESS
I20251129 18:38:16.860126 30849 scheduler_service_impl.cpp:106] [ReqID:UPD-159ee9da-3e53-4b94-9453-cfa39012631b] [UpdateTaskStatus] Task: 159ee9da-3e53-4b94-9453-cfa39012631b, State: SUCCESS
I20251129 18:38:16.860260 30850 scheduler_service_impl.cpp:106] [ReqID:UPD-9a7fdf74-f799-4d5f-8821-9be7a56e7b97] [UpdateTaskStatus] Task: 9a7fdf74-f799-4d5f-8821-9be7a56e7b97, State: SUCCESS
I20251129 18:38:16.860514 29164 scheduler_loop.cpp:163] [ReqID:DISP-159ee9da-3e53-4b94-9453-cfa39012631b] Successfully dispatched task 159ee9da-3e53-4b94-9453-cfa39012631b to worker-01
I20251129 18:38:16.860574 29167 scheduler_loop.cpp:163] [ReqID:DISP-bdc47086-de0d-4931-8853-0c6254894574] Successfully dispatched task bdc47086-de0d-4931-8853-0c6254894574 to worker-01
I20251129 18:38:16.860548 29169 scheduler_loop.cpp:163] [ReqID:DISP-9b252b76-5e22-4658-b637-afe94c5d7f47] Successfully dispatched task 9b252b76-5e22-4658-b637-afe94c5d7f47 to worker-01
I20251129 18:38:16.860569 29163 scheduler_loop.cpp:163] [ReqID:DISP-8d4d8f44-8ad9-4e73-a074-700d5a46e080] Successfully dispatched task 8d4d8f44-8ad9-4e73-a074-700d5a46e080 to worker-01
I20251129 18:38:16.860580 29170 scheduler_loop.cpp:163] [ReqID:DISP-e9d802db-78a5-4038-b807-000644e14a22] Successfully dispatched task e9d802db-78a5-4038-b807-000644e14a22 to worker-01
I20251129 18:38:16.860524 29168 scheduler_loop.cpp:163] [ReqID:DISP-9a7fdf74-f799-4d5f-8821-9be7a56e7b97] Successfully dispatched task 9a7fdf74-f799-4d5f-8821-9be7a56e7b97 to worker-01
I20251129 18:38:16.864248 29166 scheduler_loop.cpp:163] [ReqID:DISP-2fcb1914-2b39-4f59-b430-87df0ca59a05] Successfully dispatched task 2fcb1914-2b39-4f59-b430-87df0ca59a05 to worker-01
I20251129 18:38:16.864655 30849 scheduler_service_impl.cpp:106] [ReqID:UPD-bdc47086-de0d-4931-8853-0c6254894574] [UpdateTaskStatus] Task: bdc47086-de0d-4931-8853-0c6254894574, State: SUCCESS
I20251129 18:38:16.864727 30851 scheduler_service_impl.cpp:106] [ReqID:UPD-9b252b76-5e22-4658-b637-afe94c5d7f47] [UpdateTaskStatus] Task: 9b252b76-5e22-4658-b637-afe94c5d7f47, State: SUCCESS
I20251129 18:38:16.864753 30852 scheduler_service_impl.cpp:106] [ReqID:UPD-e9d802db-78a5-4038-b807-000644e14a22] [UpdateTaskStatus] Task: e9d802db-78a5-4038-b807-000644e14a22, State: SUCCESS
I20251129 18:38:16.864872 30853 scheduler_service_impl.cpp:106] [ReqID:UPD-8d4d8f44-8ad9-4e73-a074-700d5a46e080] [UpdateTaskStatus] Task: 8d4d8f44-8ad9-4e73-a074-700d5a46e080, State: SUCCESS
I20251129 18:38:16.868306 30852 scheduler_service_impl.cpp:106] [ReqID:UPD-2fcb1914-2b39-4f59-b430-87df0ca59a05] [UpdateTaskStatus] Task: 2fcb1914-2b39-4f59-b430-87df0ca59a05, State: SUCCESS
I20251129 18:38:17.348026 29165 scheduler_loop.cpp:163] [ReqID:DISP-35f6b1c9-c26b-4088-8f4f-d5ea1e4bbac3] Successfully dispatched task 35f6b1c9-c26b-4088-8f4f-d5ea1e4bbac3 to worker-01
I20251129 18:38:17.348026 30849 scheduler_service_impl.cpp:106] [ReqID:UPD-35f6b1c9-c26b-4088-8f4f-d5ea1e4bbac3] [UpdateTaskStatus] Task: 35f6b1c9-c26b-4088-8f4f-d5ea1e4bbac3, State: SUCCESS
I20251129 18:38:17.360651 29166 scheduler_loop.cpp:163] [ReqID:DISP-579e1734-a309-4186-9c43-75ade0fa50e8] Successfully dispatched task 579e1734-a309-4186-9c43-75ade0fa50e8 to worker-01
I20251129 18:38:17.360769 29167 scheduler_loop.cpp:163] [ReqID:DISP-6a5a9e45-3527-4214-849d-98f5e8ac61bb] Successfully dispatched task 6a5a9e45-3527-4214-849d-98f5e8ac61bb to worker-01
I20251129 18:38:17.361281 30849 scheduler_service_impl.cpp:106] [ReqID:UPD-579e1734-a309-4186-9c43-75ade0fa50e8] [UpdateTaskStatus] Task: 579e1734-a309-4186-9c43-75ade0fa50e8, State: SUCCESS
I20251129 18:38:17.361454 29164 scheduler_loop.cpp:163] [ReqID:DISP-73b9cca3-b8be-40af-9e09-ffd4ef97eb50] Successfully dispatched task 73b9cca3-b8be-40af-9e09-ffd4ef97eb50 to worker-01
I20251129 18:38:17.361500 29168 scheduler_loop.cpp:163] [ReqID:DISP-dda8169f-47be-42bd-91d5-9c8c87fc216d] Successfully dispatched task dda8169f-47be-42bd-91d5-9c8c87fc216d to worker-01
I20251129 18:38:17.361577 30854 scheduler_service_impl.cpp:106] [ReqID:UPD-6a5a9e45-3527-4214-849d-98f5e8ac61bb] [UpdateTaskStatus] Task: 6a5a9e45-3527-4214-849d-98f5e8ac61bb, State: SUCCESS
I20251129 18:38:17.361689 29169 scheduler_loop.cpp:163] [ReqID:DISP-1d27aa11-61d4-463e-b241-73820633764a] Successfully dispatched task 1d27aa11-61d4-463e-b241-73820633764a to worker-01
I20251129 18:38:17.361614 30870 scheduler_service_impl.cpp:106] [ReqID:UPD-dda8169f-47be-42bd-91d5-9c8c87fc216d] [UpdateTaskStatus] Task: dda8169f-47be-42bd-91d5-9c8c87fc216d, State: SUCCESS
I20251129 18:38:17.361634 29165 scheduler_loop.cpp:163] [ReqID:DISP-87c45237-b8e0-41d5-a478-cfa4cd36cc9c] Successfully dispatched task 87c45237-b8e0-41d5-a478-cfa4cd36cc9c to worker-01
I20251129 18:38:17.361796 29163 scheduler_loop.cpp:163] [ReqID:DISP-b315146f-133b-4899-9cfb-ffd0b4515a91] Successfully dispatched task b315146f-133b-4899-9cfb-ffd0b4515a91 to worker-01
I20251129 18:38:17.361819 30871 scheduler_service_impl.cpp:106] [ReqID:UPD-73b9cca3-b8be-40af-9e09-ffd4ef97eb50] [UpdateTaskStatus] Task: 73b9cca3-b8be-40af-9e09-ffd4ef97eb50, State: SUCCESS
I20251129 18:38:17.362273 29170 scheduler_loop.cpp:163] [ReqID:DISP-e32cc744-56b2-4545-9309-3e925fc91422] Successfully dispatched task e32cc744-56b2-4545-9309-3e925fc91422 to worker-01
I20251129 18:38:17.365248 29166 scheduler_loop.cpp:163] [ReqID:DISP-fb783302-baef-4902-86a6-fda488a2bb7a] Successfully dispatched task fb783302-baef-4902-86a6-fda488a2bb7a to worker-01
I20251129 18:38:17.383647 30871 scheduler_service_impl.cpp:106] [ReqID:UPD-e32cc744-56b2-4545-9309-3e925fc91422] [UpdateTaskStatus] Task: e32cc744-56b2-4545-9309-3e925fc91422, State: SUCCESS
I20251129 18:38:17.383718 30872 scheduler_service_impl.cpp:106] [ReqID:UPD-b315146f-133b-4899-9cfb-ffd0b4515a91] [UpdateTaskStatus] Task: b315146f-133b-4899-9cfb-ffd0b4515a91, State: SUCCESS
I20251129 18:38:17.383773 30873 scheduler_service_impl.cpp:106] [ReqID:UPD-87c45237-b8e0-41d5-a478-cfa4cd36cc9c] [UpdateTaskStatus] Task: 87c45237-b8e0-41d5-a478-cfa4cd36cc9c, State: SUCCESS
I20251129 18:38:17.383957 30874 scheduler_service_impl.cpp:106] [ReqID:UPD-1d27aa11-61d4-463e-b241-73820633764a] [UpdateTaskStatus] Task: 1d27aa11-61d4-463e-b241-73820633764a, State: SUCCESS
I20251129 18:38:17.387085 30872 scheduler_service_impl.cpp:106] [ReqID:UPD-fb783302-baef-4902-86a6-fda488a2bb7a] [UpdateTaskStatus] Task: fb783302-baef-4902-86a6-fda488a2bb7a, State: SUCCESS
I20251129 18:38:17.849856 29170 scheduler_loop.cpp:163] [ReqID:DISP-5a24feec-c143-4acf-956a-e05510fbc9cd] Successfully dispatched task 5a24feec-c143-4acf-956a-e05510fbc9cd to worker-01
I20251129 18:38:17.849864 29168 scheduler_loop.cpp:163] [ReqID:DISP-ea97291d-a984-483a-bed0-2bb2525bacd5] Successfully dispatched task ea97291d-a984-483a-bed0-2bb2525bacd5 to worker-01
I20251129 18:38:17.850046 30875 scheduler_service_impl.cpp:106] [ReqID:UPD-ea97291d-a984-483a-bed0-2bb2525bacd5] [UpdateTaskStatus] Task: ea97291d-a984-483a-bed0-2bb2525bacd5, State: SUCCESS
I20251129 18:38:17.850180 30874 scheduler_service_impl.cpp:106] [ReqID:UPD-5a24feec-c143-4acf-956a-e05510fbc9cd] [UpdateTaskStatus] Task: 5a24feec-c143-4acf-956a-e05510fbc9cd, State: SUCCESS
I20251129 18:38:17.850567 29167 scheduler_loop.cpp:163] [ReqID:DISP-4d5d891a-2d23-4070-aef8-baa3eeae7eb0] Successfully dispatched task 4d5d891a-2d23-4070-aef8-baa3eeae7eb0 to worker-01
I20251129 18:38:17.850621 29166 scheduler_loop.cpp:163] [ReqID:DISP-8828a93a-ed26-42e5-97f8-ba36a9d2b40c] Successfully dispatched task 8828a93a-ed26-42e5-97f8-ba36a9d2b40c to worker-01
I20251129 18:38:17.850694 29163 scheduler_loop.cpp:163] [ReqID:DISP-38b9ab15-3d74-4f52-9d69-69fe8bce669a] Successfully dispatched task 38b9ab15-3d74-4f52-9d69-69fe8bce669a to worker-01
I20251129 18:38:17.850759 29169 scheduler_loop.cpp:163] [ReqID:DISP-63f96f6a-dd1b-4f92-8fbc-bcdf418731b2] Successfully dispatched task 63f96f6a-dd1b-4f92-8fbc-bcdf418731b2 to worker-01
I20251129 18:38:17.850868 30879 scheduler_service_impl.cpp:106] [ReqID:UPD-8828a93a-ed26-42e5-97f8-ba36a9d2b40c] [UpdateTaskStatus] Task: 8828a93a-ed26-42e5-97f8-ba36a9d2b40c, State: SUCCESS
I20251129 18:38:17.851016 30880 scheduler_service_impl.cpp:106] [ReqID:UPD-4d5d891a-2d23-4070-aef8-baa3eeae7eb0] [UpdateTaskStatus] Task: 4d5d891a-2d23-4070-aef8-baa3eeae7eb0, State: SUCCESS
I20251129 18:38:17.851527 29164 scheduler_loop.cpp:163] [ReqID:DISP-31b8c9fe-98cb-4e24-b5ba-5e1a173ec461] Successfully dispatched task 31b8c9fe-98cb-4e24-b5ba-5e1a173ec461 to worker-01
I20251129 18:38:17.851639 29165 scheduler_loop.cpp:163] [ReqID:DISP-143fd4af-3257-4e96-a744-d76b1849803d] Successfully dispatched task 143fd4af-3257-4e96-a744-d76b1849803d to worker-01
I20251129 18:38:17.853677 29170 scheduler_loop.cpp:163] [ReqID:DISP-8c1abf2e-5d42-45e0-8f6c-1f6e41fe13c0] Successfully dispatched task 8c1abf2e-5d42-45e0-8f6c-1f6e41fe13c0 to worker-01
I20251129 18:38:17.854261 30879 scheduler_service_impl.cpp:106] [ReqID:UPD-38b9ab15-3d74-4f52-9d69-69fe8bce669a] [UpdateTaskStatus] Task: 38b9ab15-3d74-4f52-9d69-69fe8bce669a, State: SUCCESS
I20251129 18:38:17.854491 29168 scheduler_loop.cpp:163] [ReqID:DISP-33b9996a-12ba-436f-a192-e4058d1860f6] Successfully dispatched task 33b9996a-12ba-436f-a192-e4058d1860f6 to worker-01
I20251129 18:38:17.854687 30881 scheduler_service_impl.cpp:106] [ReqID:UPD-31b8c9fe-98cb-4e24-b5ba-5e1a173ec461] [UpdateTaskStatus] Task: 31b8c9fe-98cb-4e24-b5ba-5e1a173ec461, State: SUCCESS
I20251129 18:38:17.854782 30882 scheduler_service_impl.cpp:106] [ReqID:UPD-63f96f6a-dd1b-4f92-8fbc-bcdf418731b2] [UpdateTaskStatus] Task: 63f96f6a-dd1b-4f92-8fbc-bcdf418731b2, State: SUCCESS
I20251129 18:38:17.854894 30883 scheduler_service_impl.cpp:106] [ReqID:UPD-143fd4af-3257-4e96-a744-d76b1849803d] [UpdateTaskStatus] Task: 143fd4af-3257-4e96-a744-d76b1849803d, State: SUCCESS
I20251129 18:38:17.857390 30879 scheduler_service_impl.cpp:106] [ReqID:UPD-8c1abf2e-5d42-45e0-8f6c-1f6e41fe13c0] [UpdateTaskStatus] Task: 8c1abf2e-5d42-45e0-8f6c-1f6e41fe13c0, State: SUCCESS
I20251129 18:38:17.858175 30883 scheduler_service_impl.cpp:106] [ReqID:UPD-33b9996a-12ba-436f-a192-e4058d1860f6] [UpdateTaskStatus] Task: 33b9996a-12ba-436f-a192-e4058d1860f6, State: SUCCESS
I20251129 18:38:18.355391 30879 scheduler_service_impl.cpp:106] [ReqID:UPD-cefde3bf-570f-4704-8eae-333f5b217fb3] [UpdateTaskStatus] Task: cefde3bf-570f-4704-8eae-333f5b217fb3, State: SUCCESS
I20251129 18:38:18.355396 29164 scheduler_loop.cpp:163] [ReqID:DISP-cefde3bf-570f-4704-8eae-333f5b217fb3] Successfully dispatched task cefde3bf-570f-4704-8eae-333f5b217fb3 to worker-01
I20251129 18:38:18.356911 29168 scheduler_loop.cpp:163] [ReqID:DISP-83ef0d24-4f72-4176-9015-ac079981dee8] Successfully dispatched task 83ef0d24-4f72-4176-9015-ac079981dee8 to worker-01
I20251129 18:38:18.357261 29167 scheduler_loop.cpp:163] [ReqID:DISP-3ce3bc13-0fef-44b1-92bc-e0f73e653bad] Successfully dispatched task 3ce3bc13-0fef-44b1-92bc-e0f73e653bad to worker-01
I20251129 18:38:18.356912 29163 scheduler_loop.cpp:163] [ReqID:DISP-4574b1c9-20f9-410b-b3a9-ce81bb5f7a5e] Successfully dispatched task 4574b1c9-20f9-410b-b3a9-ce81bb5f7a5e to worker-01
I20251129 18:38:18.356947 29165 scheduler_loop.cpp:163] [ReqID:DISP-268041b3-c70e-4ddd-8950-a21a05b7459b] Successfully dispatched task 268041b3-c70e-4ddd-8950-a21a05b7459b to worker-01
I20251129 18:38:18.357220 30884 scheduler_service_impl.cpp:106] [ReqID:UPD-c5910926-7671-4523-9adb-cef4403a702d] [UpdateTaskStatus] Task: c5910926-7671-4523-9adb-cef4403a702d, State: SUCCESS
I20251129 18:38:18.357227 29169 scheduler_loop.cpp:163] [ReqID:DISP-5572141d-9fd6-4199-9097-d62eae4151b3] Successfully dispatched task 5572141d-9fd6-4199-9097-d62eae4151b3 to worker-01
I20251129 18:38:18.357241 29170 scheduler_loop.cpp:163] [ReqID:DISP-6c282756-ac8e-4ae4-87c0-fb2e224e4d79] Successfully dispatched task 6c282756-ac8e-4ae4-87c0-fb2e224e4d79 to worker-01
I20251129 18:38:18.357280 30894 scheduler_service_impl.cpp:106] [ReqID:UPD-83ef0d24-4f72-4176-9015-ac079981dee8] [UpdateTaskStatus] Task: 83ef0d24-4f72-4176-9015-ac079981dee8, State: SUCCESS
I20251129 18:38:18.356925 29166 scheduler_loop.cpp:163] [ReqID:DISP-c5910926-7671-4523-9adb-cef4403a702d] Successfully dispatched task c5910926-7671-4523-9adb-cef4403a702d to worker-01
I20251129 18:38:18.357321 30895 scheduler_service_impl.cpp:106] [ReqID:UPD-4574b1c9-20f9-410b-b3a9-ce81bb5f7a5e] [UpdateTaskStatus] Task: 4574b1c9-20f9-410b-b3a9-ce81bb5f7a5e, State: SUCCESS
I20251129 18:38:18.359596 29164 scheduler_loop.cpp:163] [ReqID:DISP-b380c3fb-9c6a-433e-8000-04947347e048] Successfully dispatched task b380c3fb-9c6a-433e-8000-04947347e048 to worker-01
I20251129 18:38:18.360451 30879 scheduler_service_impl.cpp:106] [ReqID:UPD-268041b3-c70e-4ddd-8950-a21a05b7459b] [UpdateTaskStatus] Task: 268041b3-c70e-4ddd-8950-a21a05b7459b, State: SUCCESS
I20251129 18:38:18.360805 29168 scheduler_loop.cpp:163] [ReqID:DISP-4bb89ea2-4da7-4d71-9652-21cbcabcf3a4] Successfully dispatched task 4bb89ea2-4da7-4d71-9652-21cbcabcf3a4 to worker-01
I20251129 18:38:18.361871 30895 scheduler_service_impl.cpp:106] [ReqID:UPD-5572141d-9fd6-4199-9097-d62eae4151b3] [UpdateTaskStatus] Task: 5572141d-9fd6-4199-9097-d62eae4151b3, State: SUCCESS
I20251129 18:38:18.362063 30896 scheduler_service_impl.cpp:106] [ReqID:UPD-3ce3bc13-0fef-44b1-92bc-e0f73e653bad] [UpdateTaskStatus] Task: 3ce3bc13-0fef-44b1-92bc-e0f73e653bad, State: SUCCESS
I20251129 18:38:18.362111 30897 scheduler_service_impl.cpp:106] [ReqID:UPD-6c282756-ac8e-4ae4-87c0-fb2e224e4d79] [UpdateTaskStatus] Task: 6c282756-ac8e-4ae4-87c0-fb2e224e4d79, State: SUCCESS
I20251129 18:38:18.363967 30879 scheduler_service_impl.cpp:106] [ReqID:UPD-b380c3fb-9c6a-433e-8000-04947347e048] [UpdateTaskStatus] Task: b380c3fb-9c6a-433e-8000-04947347e048, State: SUCCESS
I20251129 18:38:18.364975 30895 scheduler_service_impl.cpp:106] [ReqID:UPD-4bb89ea2-4da7-4d71-9652-21cbcabcf3a4] [UpdateTaskStatus] Task: 4bb89ea2-4da7-4d71-9652-21cbcabcf3a4, State: SUCCESS
I20251129 18:38:18.857074 30898 scheduler_service_impl.cpp:106] [ReqID:UPD-47b70c13-5110-4ec2-943b-1c8770c388e6] [UpdateTaskStatus] Task: 47b70c13-5110-4ec2-943b-1c8770c388e6, State: SUCCESS
I20251129 18:38:18.857075 29169 scheduler_loop.cpp:163] [ReqID:DISP-47b70c13-5110-4ec2-943b-1c8770c388e6] Successfully dispatched task 47b70c13-5110-4ec2-943b-1c8770c388e6 to worker-01
I20251129 18:38:18.858161 29167 scheduler_loop.cpp:163] [ReqID:DISP-45aca93b-8144-4d25-8287-a5b43d5c34ab] Successfully dispatched task 45aca93b-8144-4d25-8287-a5b43d5c34ab to worker-01
I20251129 18:38:18.858338 30897 scheduler_service_impl.cpp:106] [ReqID:UPD-d3cac321-c3ab-4056-9a00-3af043335dfd] [UpdateTaskStatus] Task: d3cac321-c3ab-4056-9a00-3af043335dfd, State: SUCCESS
I20251129 18:38:18.858438 30909 scheduler_service_impl.cpp:106] [ReqID:UPD-45aca93b-8144-4d25-8287-a5b43d5c34ab] [UpdateTaskStatus] Task: 45aca93b-8144-4d25-8287-a5b43d5c34ab, State: SUCCESS
I20251129 18:38:18.858569 29163 scheduler_loop.cpp:163] [ReqID:DISP-d3cac321-c3ab-4056-9a00-3af043335dfd] Successfully dispatched task d3cac321-c3ab-4056-9a00-3af043335dfd to worker-01
I20251129 18:38:18.858952 30910 scheduler_service_impl.cpp:106] [ReqID:UPD-ca0d035c-72f2-4236-a484-75d3b7c3c851] [UpdateTaskStatus] Task: ca0d035c-72f2-4236-a484-75d3b7c3c851, State: SUCCESS
I20251129 18:38:18.859050 29164 scheduler_loop.cpp:163] [ReqID:DISP-b76f0b5d-6e2f-467f-8ef8-b1a538c4079f] Successfully dispatched task b76f0b5d-6e2f-467f-8ef8-b1a538c4079f to worker-01
I20251129 18:38:18.859063 29168 scheduler_loop.cpp:163] [ReqID:DISP-ca0d035c-72f2-4236-a484-75d3b7c3c851] Successfully dispatched task ca0d035c-72f2-4236-a484-75d3b7c3c851 to worker-01
I20251129 18:38:18.859119 29166 scheduler_loop.cpp:163] [ReqID:DISP-096f7eaa-8e3d-47dc-b8dd-c10fdd73158f] Successfully dispatched task 096f7eaa-8e3d-47dc-b8dd-c10fdd73158f to worker-01
I20251129 18:38:18.859143 29165 scheduler_loop.cpp:163] [ReqID:DISP-d27f9d08-9a26-4f2d-99d1-7595269b0ccf] Successfully dispatched task d27f9d08-9a26-4f2d-99d1-7595269b0ccf to worker-01
I20251129 18:38:18.859054 29170 scheduler_loop.cpp:163] [ReqID:DISP-da2f62f9-6d70-4dbe-bda6-c850b41420cb] Successfully dispatched task da2f62f9-6d70-4dbe-bda6-c850b41420cb to worker-01
I20251129 18:38:18.862316 30909 scheduler_service_impl.cpp:106] [ReqID:UPD-096f7eaa-8e3d-47dc-b8dd-c10fdd73158f] [UpdateTaskStatus] Task: 096f7eaa-8e3d-47dc-b8dd-c10fdd73158f, State: SUCCESS
I20251129 18:38:18.862382 29169 scheduler_loop.cpp:163] [ReqID:DISP-def25e2f-2f8a-42d1-9c7d-92ff4075f301] Successfully dispatched task def25e2f-2f8a-42d1-9c7d-92ff4075f301 to worker-01
I20251129 18:38:18.862977 30911 scheduler_service_impl.cpp:106] [ReqID:UPD-b76f0b5d-6e2f-467f-8ef8-b1a538c4079f] [UpdateTaskStatus] Task: b76f0b5d-6e2f-467f-8ef8-b1a538c4079f, State: SUCCESS
I20251129 18:38:18.862977 29167 scheduler_loop.cpp:163] [ReqID:DISP-10ee0d7c-ccb2-4578-984a-3b4955e31252] Successfully dispatched task 10ee0d7c-ccb2-4578-984a-3b4955e31252 to worker-01
I20251129 18:38:18.863021 30912 scheduler_service_impl.cpp:106] [ReqID:UPD-da2f62f9-6d70-4dbe-bda6-c850b41420cb] [UpdateTaskStatus] Task: da2f62f9-6d70-4dbe-bda6-c850b41420cb, State: SUCCESS
I20251129 18:38:18.863205 30913 scheduler_service_impl.cpp:106] [ReqID:UPD-d27f9d08-9a26-4f2d-99d1-7595269b0ccf] [UpdateTaskStatus] Task: d27f9d08-9a26-4f2d-99d1-7595269b0ccf, State: SUCCESS
I20251129 18:38:18.866407 30909 scheduler_service_impl.cpp:106] [ReqID:UPD-def25e2f-2f8a-42d1-9c7d-92ff4075f301] [UpdateTaskStatus] Task: def25e2f-2f8a-42d1-9c7d-92ff4075f301, State: SUCCESS
I20251129 18:38:18.867842 30912 scheduler_service_impl.cpp:106] [ReqID:UPD-10ee0d7c-ccb2-4578-984a-3b4955e31252] [UpdateTaskStatus] Task: 10ee0d7c-ccb2-4578-984a-3b4955e31252, State: SUCCESS
I20251129 18:38:19.356402 29163 scheduler_loop.cpp:163] [ReqID:DISP-f41a3885-9b6c-456c-bb8c-0533a0e99a31] Successfully dispatched task f41a3885-9b6c-456c-bb8c-0533a0e99a31 to worker-01
I20251129 18:38:19.356885 30909 scheduler_service_impl.cpp:106] [ReqID:UPD-f41a3885-9b6c-456c-bb8c-0533a0e99a31] [UpdateTaskStatus] Task: f41a3885-9b6c-456c-bb8c-0533a0e99a31, State: SUCCESS
I20251129 18:38:19.362039 29167 scheduler_loop.cpp:163] [ReqID:DISP-56c83304-7b94-4afe-ae2c-f395c765f9dd] Successfully dispatched task 56c83304-7b94-4afe-ae2c-f395c765f9dd to worker-01
I20251129 18:38:19.362205 30920 scheduler_service_impl.cpp:106] [ReqID:UPD-56c83304-7b94-4afe-ae2c-f395c765f9dd] [UpdateTaskStatus] Task: 56c83304-7b94-4afe-ae2c-f395c765f9dd, State: SUCCESS
I20251129 18:38:19.362159 30914 scheduler_service_impl.cpp:106] [ReqID:UPD-80833c85-9b8a-46e1-8bff-21ef496f0455] [UpdateTaskStatus] Task: 80833c85-9b8a-46e1-8bff-21ef496f0455, State: SUCCESS
I20251129 18:38:19.362272 29170 scheduler_loop.cpp:163] [ReqID:DISP-3b6e8e0a-e208-4a6b-874a-e6b99f5c48cb] Successfully dispatched task 3b6e8e0a-e208-4a6b-874a-e6b99f5c48cb to worker-01
I20251129 18:38:19.362303 29169 scheduler_loop.cpp:163] [ReqID:DISP-80833c85-9b8a-46e1-8bff-21ef496f0455] Successfully dispatched task 80833c85-9b8a-46e1-8bff-21ef496f0455 to worker-01
I20251129 18:38:19.362326 29164 scheduler_loop.cpp:163] [ReqID:DISP-d915e888-6798-4b1d-8fc8-dc2564fbd438] Successfully dispatched task d915e888-6798-4b1d-8fc8-dc2564fbd438 to worker-01
I20251129 18:38:19.362372 29166 scheduler_loop.cpp:163] [ReqID:DISP-5689b2d5-11be-46e0-8550-b1f0a9d08e09] Successfully dispatched task 5689b2d5-11be-46e0-8550-b1f0a9d08e09 to worker-01
I20251129 18:38:19.362380 29165 scheduler_loop.cpp:163] [ReqID:DISP-6a66b9a5-2628-430c-8f63-16441bf15d1e] Successfully dispatched task 6a66b9a5-2628-430c-8f63-16441bf15d1e to worker-01
I20251129 18:38:19.362406 29168 scheduler_loop.cpp:163] [ReqID:DISP-5425675d-4db3-420f-95cf-02570c557b47] Successfully dispatched task 5425675d-4db3-420f-95cf-02570c557b47 to worker-01
I20251129 18:38:19.362581 30909 scheduler_service_impl.cpp:106] [ReqID:UPD-3b6e8e0a-e208-4a6b-874a-e6b99f5c48cb] [UpdateTaskStatus] Task: 3b6e8e0a-e208-4a6b-874a-e6b99f5c48cb, State: SUCCESS
I20251129 18:38:19.363174 30921 scheduler_service_impl.cpp:106] [ReqID:UPD-d915e888-6798-4b1d-8fc8-dc2564fbd438] [UpdateTaskStatus] Task: d915e888-6798-4b1d-8fc8-dc2564fbd438, State: SUCCESS
I20251129 18:38:19.363301 29163 scheduler_loop.cpp:163] [ReqID:DISP-020cf835-95f0-48d3-a0c7-a447581df717] Successfully dispatched task 020cf835-95f0-48d3-a0c7-a447581df717 to worker-01
I20251129 18:38:19.369223 29167 scheduler_loop.cpp:163] [ReqID:DISP-c203db50-c928-4371-ba23-4d7148622245] Successfully dispatched task c203db50-c928-4371-ba23-4d7148622245 to worker-01
I20251129 18:38:19.370096 30921 scheduler_service_impl.cpp:106] [ReqID:UPD-6a66b9a5-2628-430c-8f63-16441bf15d1e] [UpdateTaskStatus] Task: 6a66b9a5-2628-430c-8f63-16441bf15d1e, State: SUCCESS
I20251129 18:38:19.370208 30922 scheduler_service_impl.cpp:106] [ReqID:UPD-5689b2d5-11be-46e0-8550-b1f0a9d08e09] [UpdateTaskStatus] Task: 5689b2d5-11be-46e0-8550-b1f0a9d08e09, State: SUCCESS
I20251129 18:38:19.370270 30923 scheduler_service_impl.cpp:106] [ReqID:UPD-020cf835-95f0-48d3-a0c7-a447581df717] [UpdateTaskStatus] Task: 020cf835-95f0-48d3-a0c7-a447581df717, State: SUCCESS
